[2023-08-15 20:09:53,774] {taskinstance.py:1159} INFO - Dependencies all met for <TaskInstance: dados_climaticos.cria_pasta_mes_ano scheduled__2023-05-01T00:00:00+00:00 [queued]>
[2023-08-15 20:09:53,779] {taskinstance.py:1159} INFO - Dependencies all met for <TaskInstance: dados_climaticos.cria_pasta_mes_ano scheduled__2023-05-01T00:00:00+00:00 [queued]>
[2023-08-15 20:09:53,779] {taskinstance.py:1356} INFO - 
--------------------------------------------------------------------------------
[2023-08-15 20:09:53,779] {taskinstance.py:1357} INFO - Starting attempt 1 of 1
[2023-08-15 20:09:53,779] {taskinstance.py:1358} INFO - 
--------------------------------------------------------------------------------
[2023-08-15 20:09:53,804] {taskinstance.py:1377} INFO - Executing <Task(BashOperator): cria_pasta_mes_ano> on 2023-05-01 00:00:00+00:00
[2023-08-15 20:09:53,808] {standard_task_runner.py:52} INFO - Started process 47566 to run task
[2023-08-15 20:09:53,813] {standard_task_runner.py:79} INFO - Running: ['airflow', 'tasks', 'run', 'dados_climaticos', 'cria_pasta_mes_ano', 'scheduled__2023-05-01T00:00:00+00:00', '--job-id', '114', '--raw', '--subdir', 'DAGS_FOLDER/dados_climatics.py', '--cfg-path', '/tmp/tmpr4i9ntsb', '--error-file', '/tmp/tmptmo8wv69']
[2023-08-15 20:09:53,813] {standard_task_runner.py:80} INFO - Job 114: Subtask cria_pasta_mes_ano
[2023-08-15 20:09:53,876] {task_command.py:370} INFO - Running <TaskInstance: dados_climaticos.cria_pasta_mes_ano scheduled__2023-05-01T00:00:00+00:00 [running]> on host ubuntu.internal.cloudapp.net
[2023-08-15 20:09:53,937] {taskinstance.py:1889} ERROR - Task failed with exception
Traceback (most recent call last):
  File "/home/guilherme/airflow/venv/lib/python3.9/site-packages/airflow/models/taskinstance.py", line 1451, in _run_raw_task
    self._execute_task_with_callbacks(context, test_mode)
  File "/home/guilherme/airflow/venv/lib/python3.9/site-packages/airflow/models/taskinstance.py", line 1555, in _execute_task_with_callbacks
    task_orig = self.render_templates(context=context)
  File "/home/guilherme/airflow/venv/lib/python3.9/site-packages/airflow/models/taskinstance.py", line 2212, in render_templates
    rendered_task = self.task.render_template_fields(context)
  File "/home/guilherme/airflow/venv/lib/python3.9/site-packages/airflow/models/baseoperator.py", line 1185, in render_template_fields
    self._do_render_template_fields(self, self.template_fields, context, jinja_env, set())
  File "/home/guilherme/airflow/venv/lib/python3.9/site-packages/airflow/utils/session.py", line 71, in wrapper
    return func(*args, session=session, **kwargs)
  File "/home/guilherme/airflow/venv/lib/python3.9/site-packages/airflow/models/abstractoperator.py", line 344, in _do_render_template_fields
    rendered_content = self.render_template(
  File "/home/guilherme/airflow/venv/lib/python3.9/site-packages/airflow/models/abstractoperator.py", line 387, in render_template
    template = jinja_env.from_string(value)
  File "/home/guilherme/airflow/venv/lib/python3.9/site-packages/jinja2/environment.py", line 1092, in from_string
    return cls.from_code(self, self.compile(source), gs, None)
  File "/home/guilherme/airflow/venv/lib/python3.9/site-packages/jinja2/environment.py", line 757, in compile
    self.handle_exception(source=source_hint)
  File "/home/guilherme/airflow/venv/lib/python3.9/site-packages/jinja2/environment.py", line 925, in handle_exception
    raise rewrite_traceback_stack(source=source)
  File "<unknown>", line 1, in template
jinja2.exceptions.TemplateSyntaxError: unexpected end of template, expected ','.
[2023-08-15 20:09:53,944] {taskinstance.py:1395} INFO - Marking task as FAILED. dag_id=dados_climaticos, task_id=cria_pasta_mes_ano, execution_date=20230501T000000, start_date=20230815T200953, end_date=20230815T200953
[2023-08-15 20:09:53,972] {standard_task_runner.py:92} ERROR - Failed to execute job 114 for task cria_pasta_mes_ano (unexpected end of template, expected ','.; 47566)
[2023-08-15 20:09:53,984] {local_task_job.py:156} INFO - Task exited with return code 1
[2023-08-15 20:09:54,024] {local_task_job.py:273} INFO - 0 downstream tasks scheduled from follow-on schedule check
[2023-08-15 20:29:51,162] {taskinstance.py:1159} INFO - Dependencies all met for <TaskInstance: dados_climaticos.cria_pasta_mes_ano scheduled__2023-05-01T00:00:00+00:00 [queued]>
[2023-08-15 20:29:51,169] {taskinstance.py:1159} INFO - Dependencies all met for <TaskInstance: dados_climaticos.cria_pasta_mes_ano scheduled__2023-05-01T00:00:00+00:00 [queued]>
[2023-08-15 20:29:51,169] {taskinstance.py:1356} INFO - 
--------------------------------------------------------------------------------
[2023-08-15 20:29:51,169] {taskinstance.py:1357} INFO - Starting attempt 1 of 1
[2023-08-15 20:29:51,169] {taskinstance.py:1358} INFO - 
--------------------------------------------------------------------------------
[2023-08-15 20:29:51,193] {taskinstance.py:1377} INFO - Executing <Task(BashOperator): cria_pasta_mes_ano> on 2023-05-01 00:00:00+00:00
[2023-08-15 20:29:51,196] {standard_task_runner.py:52} INFO - Started process 52180 to run task
[2023-08-15 20:29:51,201] {standard_task_runner.py:79} INFO - Running: ['airflow', 'tasks', 'run', 'dados_climaticos', 'cria_pasta_mes_ano', 'scheduled__2023-05-01T00:00:00+00:00', '--job-id', '185', '--raw', '--subdir', 'DAGS_FOLDER/dados_climatics.py', '--cfg-path', '/tmp/tmpxnyahmwb', '--error-file', '/tmp/tmpu5o71zib']
[2023-08-15 20:29:51,201] {standard_task_runner.py:80} INFO - Job 185: Subtask cria_pasta_mes_ano
[2023-08-15 20:29:51,260] {task_command.py:370} INFO - Running <TaskInstance: dados_climaticos.cria_pasta_mes_ano scheduled__2023-05-01T00:00:00+00:00 [running]> on host ubuntu.internal.cloudapp.net
[2023-08-15 20:29:51,363] {taskinstance.py:1569} INFO - Exporting the following env vars:
AIRFLOW_CTX_DAG_OWNER=airflow
AIRFLOW_CTX_DAG_ID=dados_climaticos
AIRFLOW_CTX_TASK_ID=cria_pasta_mes_ano
AIRFLOW_CTX_EXECUTION_DATE=2023-05-01T00:00:00+00:00
AIRFLOW_CTX_TRY_NUMBER=1
AIRFLOW_CTX_DAG_RUN_ID=scheduled__2023-05-01T00:00:00+00:00
[2023-08-15 20:29:51,364] {subprocess.py:62} INFO - Tmp dir root location: 
 /tmp
[2023-08-15 20:29:51,364] {subprocess.py:74} INFO - Running command: ['bash', '-c', 'mkdir -p "/home/guilherme/airflow/semana=2023-05"']
[2023-08-15 20:29:51,371] {subprocess.py:85} INFO - Output:
[2023-08-15 20:29:51,374] {subprocess.py:96} INFO - Command exited with return code 0
[2023-08-15 20:29:51,410] {taskinstance.py:1395} INFO - Marking task as SUCCESS. dag_id=dados_climaticos, task_id=cria_pasta_mes_ano, execution_date=20230501T000000, start_date=20230815T202951, end_date=20230815T202951
[2023-08-15 20:29:51,453] {local_task_job.py:156} INFO - Task exited with return code 0
[2023-08-15 20:29:51,488] {local_task_job.py:273} INFO - 1 downstream tasks scheduled from follow-on schedule check
[2023-08-15 20:44:19,815] {taskinstance.py:1159} INFO - Dependencies all met for <TaskInstance: dados_climaticos.cria_pasta_mes_ano scheduled__2023-05-01T00:00:00+00:00 [queued]>
[2023-08-15 20:44:19,821] {taskinstance.py:1159} INFO - Dependencies all met for <TaskInstance: dados_climaticos.cria_pasta_mes_ano scheduled__2023-05-01T00:00:00+00:00 [queued]>
[2023-08-15 20:44:19,821] {taskinstance.py:1356} INFO - 
--------------------------------------------------------------------------------
[2023-08-15 20:44:19,821] {taskinstance.py:1357} INFO - Starting attempt 1 of 1
[2023-08-15 20:44:19,821] {taskinstance.py:1358} INFO - 
--------------------------------------------------------------------------------
[2023-08-15 20:44:19,848] {taskinstance.py:1377} INFO - Executing <Task(BashOperator): cria_pasta_mes_ano> on 2023-05-01 00:00:00+00:00
[2023-08-15 20:44:19,851] {standard_task_runner.py:52} INFO - Started process 57275 to run task
[2023-08-15 20:44:19,856] {standard_task_runner.py:79} INFO - Running: ['airflow', 'tasks', 'run', 'dados_climaticos', 'cria_pasta_mes_ano', 'scheduled__2023-05-01T00:00:00+00:00', '--job-id', '285', '--raw', '--subdir', 'DAGS_FOLDER/dados_climatics.py', '--cfg-path', '/tmp/tmp5zxzzi1z', '--error-file', '/tmp/tmpem5i0ifa']
[2023-08-15 20:44:19,857] {standard_task_runner.py:80} INFO - Job 285: Subtask cria_pasta_mes_ano
[2023-08-15 20:44:19,913] {task_command.py:370} INFO - Running <TaskInstance: dados_climaticos.cria_pasta_mes_ano scheduled__2023-05-01T00:00:00+00:00 [running]> on host ubuntu.internal.cloudapp.net
[2023-08-15 20:44:19,985] {taskinstance.py:1569} INFO - Exporting the following env vars:
AIRFLOW_CTX_DAG_OWNER=airflow
AIRFLOW_CTX_DAG_ID=dados_climaticos
AIRFLOW_CTX_TASK_ID=cria_pasta_mes_ano
AIRFLOW_CTX_EXECUTION_DATE=2023-05-01T00:00:00+00:00
AIRFLOW_CTX_TRY_NUMBER=1
AIRFLOW_CTX_DAG_RUN_ID=scheduled__2023-05-01T00:00:00+00:00
[2023-08-15 20:44:19,987] {subprocess.py:62} INFO - Tmp dir root location: 
 /tmp
[2023-08-15 20:44:19,987] {subprocess.py:74} INFO - Running command: ['bash', '-c', 'mkdir -p "/home/guilherme/airflow/dados/semana=2023-05"']
[2023-08-15 20:44:19,995] {subprocess.py:85} INFO - Output:
[2023-08-15 20:44:19,997] {subprocess.py:96} INFO - Command exited with return code 0
[2023-08-15 20:44:20,034] {taskinstance.py:1395} INFO - Marking task as SUCCESS. dag_id=dados_climaticos, task_id=cria_pasta_mes_ano, execution_date=20230501T000000, start_date=20230815T204419, end_date=20230815T204420
[2023-08-15 20:44:20,068] {local_task_job.py:156} INFO - Task exited with return code 0
[2023-08-15 20:44:20,103] {local_task_job.py:273} INFO - 1 downstream tasks scheduled from follow-on schedule check
