[2023-08-15 20:00:44,153] {taskinstance.py:1159} INFO - Dependencies all met for <TaskInstance: dados_climaticos.cria_pasta scheduled__2023-05-08T00:00:00+00:00 [queued]>
[2023-08-15 20:00:44,157] {taskinstance.py:1159} INFO - Dependencies all met for <TaskInstance: dados_climaticos.cria_pasta scheduled__2023-05-08T00:00:00+00:00 [queued]>
[2023-08-15 20:00:44,158] {taskinstance.py:1356} INFO - 
--------------------------------------------------------------------------------
[2023-08-15 20:00:44,158] {taskinstance.py:1357} INFO - Starting attempt 1 of 1
[2023-08-15 20:00:44,158] {taskinstance.py:1358} INFO - 
--------------------------------------------------------------------------------
[2023-08-15 20:00:44,179] {taskinstance.py:1377} INFO - Executing <Task(BashOperator): cria_pasta> on 2023-05-08 00:00:00+00:00
[2023-08-15 20:00:44,183] {standard_task_runner.py:52} INFO - Started process 42644 to run task
[2023-08-15 20:00:44,187] {standard_task_runner.py:79} INFO - Running: ['airflow', 'tasks', 'run', 'dados_climaticos', 'cria_pasta', 'scheduled__2023-05-08T00:00:00+00:00', '--job-id', '55', '--raw', '--subdir', 'DAGS_FOLDER/dados_climatics.py', '--cfg-path', '/tmp/tmprt1tn9bu', '--error-file', '/tmp/tmpm5uyz9b5']
[2023-08-15 20:00:44,187] {standard_task_runner.py:80} INFO - Job 55: Subtask cria_pasta
[2023-08-15 20:00:44,236] {task_command.py:370} INFO - Running <TaskInstance: dados_climaticos.cria_pasta scheduled__2023-05-08T00:00:00+00:00 [running]> on host ubuntu.internal.cloudapp.net
[2023-08-15 20:00:44,272] {taskinstance.py:1889} ERROR - Task failed with exception
Traceback (most recent call last):
  File "/home/guilherme/airflow/venv/lib/python3.9/site-packages/airflow/models/taskinstance.py", line 1451, in _run_raw_task
    self._execute_task_with_callbacks(context, test_mode)
  File "/home/guilherme/airflow/venv/lib/python3.9/site-packages/airflow/models/taskinstance.py", line 1555, in _execute_task_with_callbacks
    task_orig = self.render_templates(context=context)
  File "/home/guilherme/airflow/venv/lib/python3.9/site-packages/airflow/models/taskinstance.py", line 2212, in render_templates
    rendered_task = self.task.render_template_fields(context)
  File "/home/guilherme/airflow/venv/lib/python3.9/site-packages/airflow/models/baseoperator.py", line 1185, in render_template_fields
    self._do_render_template_fields(self, self.template_fields, context, jinja_env, set())
  File "/home/guilherme/airflow/venv/lib/python3.9/site-packages/airflow/utils/session.py", line 71, in wrapper
    return func(*args, session=session, **kwargs)
  File "/home/guilherme/airflow/venv/lib/python3.9/site-packages/airflow/models/abstractoperator.py", line 344, in _do_render_template_fields
    rendered_content = self.render_template(
  File "/home/guilherme/airflow/venv/lib/python3.9/site-packages/airflow/models/abstractoperator.py", line 387, in render_template
    template = jinja_env.from_string(value)
  File "/home/guilherme/airflow/venv/lib/python3.9/site-packages/jinja2/environment.py", line 1092, in from_string
    return cls.from_code(self, self.compile(source), gs, None)
  File "/home/guilherme/airflow/venv/lib/python3.9/site-packages/jinja2/environment.py", line 757, in compile
    self.handle_exception(source=source_hint)
  File "/home/guilherme/airflow/venv/lib/python3.9/site-packages/jinja2/environment.py", line 925, in handle_exception
    raise rewrite_traceback_stack(source=source)
  File "<unknown>", line 1, in template
jinja2.exceptions.TemplateSyntaxError: unexpected end of template, expected ','.
[2023-08-15 20:00:44,276] {taskinstance.py:1395} INFO - Marking task as FAILED. dag_id=dados_climaticos, task_id=cria_pasta, execution_date=20230508T000000, start_date=20230815T200044, end_date=20230815T200044
[2023-08-15 20:00:44,295] {standard_task_runner.py:92} ERROR - Failed to execute job 55 for task cria_pasta (unexpected end of template, expected ','.; 42644)
[2023-08-15 20:00:44,318] {local_task_job.py:156} INFO - Task exited with return code 1
[2023-08-15 20:00:44,358] {local_task_job.py:273} INFO - 0 downstream tasks scheduled from follow-on schedule check
[2023-08-15 20:04:30,249] {taskinstance.py:1159} INFO - Dependencies all met for <TaskInstance: dados_climaticos.cria_pasta scheduled__2023-05-08T00:00:00+00:00 [queued]>
[2023-08-15 20:04:30,255] {taskinstance.py:1159} INFO - Dependencies all met for <TaskInstance: dados_climaticos.cria_pasta scheduled__2023-05-08T00:00:00+00:00 [queued]>
[2023-08-15 20:04:30,255] {taskinstance.py:1356} INFO - 
--------------------------------------------------------------------------------
[2023-08-15 20:04:30,255] {taskinstance.py:1357} INFO - Starting attempt 1 of 1
[2023-08-15 20:04:30,255] {taskinstance.py:1358} INFO - 
--------------------------------------------------------------------------------
[2023-08-15 20:04:30,278] {taskinstance.py:1377} INFO - Executing <Task(BashOperator): cria_pasta> on 2023-05-08 00:00:00+00:00
[2023-08-15 20:04:30,282] {standard_task_runner.py:52} INFO - Started process 45107 to run task
[2023-08-15 20:04:30,287] {standard_task_runner.py:79} INFO - Running: ['airflow', 'tasks', 'run', 'dados_climaticos', 'cria_pasta', 'scheduled__2023-05-08T00:00:00+00:00', '--job-id', '60', '--raw', '--subdir', 'DAGS_FOLDER/dados_climatics.py', '--cfg-path', '/tmp/tmp9z4kfm6e', '--error-file', '/tmp/tmp0x11pips']
[2023-08-15 20:04:30,287] {standard_task_runner.py:80} INFO - Job 60: Subtask cria_pasta
[2023-08-15 20:04:30,343] {task_command.py:370} INFO - Running <TaskInstance: dados_climaticos.cria_pasta scheduled__2023-05-08T00:00:00+00:00 [running]> on host ubuntu.internal.cloudapp.net
[2023-08-15 20:04:30,380] {taskinstance.py:1889} ERROR - Task failed with exception
Traceback (most recent call last):
  File "/home/guilherme/airflow/venv/lib/python3.9/site-packages/airflow/models/taskinstance.py", line 1451, in _run_raw_task
    self._execute_task_with_callbacks(context, test_mode)
  File "/home/guilherme/airflow/venv/lib/python3.9/site-packages/airflow/models/taskinstance.py", line 1555, in _execute_task_with_callbacks
    task_orig = self.render_templates(context=context)
  File "/home/guilherme/airflow/venv/lib/python3.9/site-packages/airflow/models/taskinstance.py", line 2212, in render_templates
    rendered_task = self.task.render_template_fields(context)
  File "/home/guilherme/airflow/venv/lib/python3.9/site-packages/airflow/models/baseoperator.py", line 1185, in render_template_fields
    self._do_render_template_fields(self, self.template_fields, context, jinja_env, set())
  File "/home/guilherme/airflow/venv/lib/python3.9/site-packages/airflow/utils/session.py", line 71, in wrapper
    return func(*args, session=session, **kwargs)
  File "/home/guilherme/airflow/venv/lib/python3.9/site-packages/airflow/models/abstractoperator.py", line 344, in _do_render_template_fields
    rendered_content = self.render_template(
  File "/home/guilherme/airflow/venv/lib/python3.9/site-packages/airflow/models/abstractoperator.py", line 387, in render_template
    template = jinja_env.from_string(value)
  File "/home/guilherme/airflow/venv/lib/python3.9/site-packages/jinja2/environment.py", line 1092, in from_string
    return cls.from_code(self, self.compile(source), gs, None)
  File "/home/guilherme/airflow/venv/lib/python3.9/site-packages/jinja2/environment.py", line 757, in compile
    self.handle_exception(source=source_hint)
  File "/home/guilherme/airflow/venv/lib/python3.9/site-packages/jinja2/environment.py", line 925, in handle_exception
    raise rewrite_traceback_stack(source=source)
  File "<unknown>", line 1, in template
jinja2.exceptions.TemplateSyntaxError: unexpected end of template, expected ','.
[2023-08-15 20:04:30,384] {taskinstance.py:1395} INFO - Marking task as FAILED. dag_id=dados_climaticos, task_id=cria_pasta, execution_date=20230508T000000, start_date=20230815T200430, end_date=20230815T200430
[2023-08-15 20:04:30,407] {standard_task_runner.py:92} ERROR - Failed to execute job 60 for task cria_pasta (unexpected end of template, expected ','.; 45107)
[2023-08-15 20:04:30,418] {local_task_job.py:156} INFO - Task exited with return code 1
[2023-08-15 20:04:30,457] {local_task_job.py:273} INFO - 0 downstream tasks scheduled from follow-on schedule check
[2023-08-15 20:11:06,766] {taskinstance.py:1159} INFO - Dependencies all met for <TaskInstance: dados_climaticos.cria_pasta scheduled__2023-05-08T00:00:00+00:00 [queued]>
[2023-08-15 20:11:06,790] {taskinstance.py:1159} INFO - Dependencies all met for <TaskInstance: dados_climaticos.cria_pasta scheduled__2023-05-08T00:00:00+00:00 [queued]>
[2023-08-15 20:11:06,790] {taskinstance.py:1356} INFO - 
--------------------------------------------------------------------------------
[2023-08-15 20:11:06,790] {taskinstance.py:1357} INFO - Starting attempt 1 of 1
[2023-08-15 20:11:06,790] {taskinstance.py:1358} INFO - 
--------------------------------------------------------------------------------
[2023-08-15 20:11:06,855] {taskinstance.py:1377} INFO - Executing <Task(BashOperator): cria_pasta> on 2023-05-08 00:00:00+00:00
[2023-08-15 20:11:06,858] {standard_task_runner.py:52} INFO - Started process 47760 to run task
[2023-08-15 20:11:06,863] {standard_task_runner.py:79} INFO - Running: ['airflow', 'tasks', 'run', 'dados_climaticos', 'cria_pasta', 'scheduled__2023-05-08T00:00:00+00:00', '--job-id', '117', '--raw', '--subdir', 'DAGS_FOLDER/dados_climatics.py', '--cfg-path', '/tmp/tmp1f89opm9', '--error-file', '/tmp/tmp19g9sels']
[2023-08-15 20:11:06,864] {standard_task_runner.py:80} INFO - Job 117: Subtask cria_pasta
[2023-08-15 20:11:06,999] {task_command.py:370} INFO - Running <TaskInstance: dados_climaticos.cria_pasta scheduled__2023-05-08T00:00:00+00:00 [running]> on host ubuntu.internal.cloudapp.net
[2023-08-15 20:11:07,178] {taskinstance.py:1569} INFO - Exporting the following env vars:
AIRFLOW_CTX_DAG_OWNER=airflow
AIRFLOW_CTX_DAG_ID=dados_climaticos
AIRFLOW_CTX_TASK_ID=cria_pasta
AIRFLOW_CTX_EXECUTION_DATE=2023-05-08T00:00:00+00:00
AIRFLOW_CTX_TRY_NUMBER=1
AIRFLOW_CTX_DAG_RUN_ID=scheduled__2023-05-08T00:00:00+00:00
[2023-08-15 20:11:07,184] {subprocess.py:62} INFO - Tmp dir root location: 
 /tmp
[2023-08-15 20:11:07,184] {subprocess.py:74} INFO - Running command: ['bash', '-c', 'mkdir -p "/home/guilherme/airflow/semana=2023-05-15"']
[2023-08-15 20:11:07,211] {subprocess.py:85} INFO - Output:
[2023-08-15 20:11:07,222] {subprocess.py:96} INFO - Command exited with return code 0
[2023-08-15 20:11:07,280] {taskinstance.py:1395} INFO - Marking task as SUCCESS. dag_id=dados_climaticos, task_id=cria_pasta, execution_date=20230508T000000, start_date=20230815T201106, end_date=20230815T201107
[2023-08-15 20:11:07,341] {local_task_job.py:156} INFO - Task exited with return code 0
[2023-08-15 20:11:07,436] {local_task_job.py:273} INFO - 1 downstream tasks scheduled from follow-on schedule check
