[2023-08-15 20:00:39,127] {taskinstance.py:1159} INFO - Dependencies all met for <TaskInstance: dados_climaticos.cria_pasta scheduled__2023-04-24T00:00:00+00:00 [queued]>
[2023-08-15 20:00:39,132] {taskinstance.py:1159} INFO - Dependencies all met for <TaskInstance: dados_climaticos.cria_pasta scheduled__2023-04-24T00:00:00+00:00 [queued]>
[2023-08-15 20:00:39,132] {taskinstance.py:1356} INFO - 
--------------------------------------------------------------------------------
[2023-08-15 20:00:39,132] {taskinstance.py:1357} INFO - Starting attempt 1 of 1
[2023-08-15 20:00:39,132] {taskinstance.py:1358} INFO - 
--------------------------------------------------------------------------------
[2023-08-15 20:00:39,159] {taskinstance.py:1377} INFO - Executing <Task(BashOperator): cria_pasta> on 2023-04-24 00:00:00+00:00
[2023-08-15 20:00:39,162] {standard_task_runner.py:52} INFO - Started process 42584 to run task
[2023-08-15 20:00:39,166] {standard_task_runner.py:79} INFO - Running: ['airflow', 'tasks', 'run', 'dados_climaticos', 'cria_pasta', 'scheduled__2023-04-24T00:00:00+00:00', '--job-id', '53', '--raw', '--subdir', 'DAGS_FOLDER/dados_climatics.py', '--cfg-path', '/tmp/tmpnvcrzba8', '--error-file', '/tmp/tmpgw_4rllv']
[2023-08-15 20:00:39,166] {standard_task_runner.py:80} INFO - Job 53: Subtask cria_pasta
[2023-08-15 20:00:39,212] {task_command.py:370} INFO - Running <TaskInstance: dados_climaticos.cria_pasta scheduled__2023-04-24T00:00:00+00:00 [running]> on host ubuntu.internal.cloudapp.net
[2023-08-15 20:00:39,247] {taskinstance.py:1889} ERROR - Task failed with exception
Traceback (most recent call last):
  File "/home/guilherme/airflow/venv/lib/python3.9/site-packages/airflow/models/taskinstance.py", line 1451, in _run_raw_task
    self._execute_task_with_callbacks(context, test_mode)
  File "/home/guilherme/airflow/venv/lib/python3.9/site-packages/airflow/models/taskinstance.py", line 1555, in _execute_task_with_callbacks
    task_orig = self.render_templates(context=context)
  File "/home/guilherme/airflow/venv/lib/python3.9/site-packages/airflow/models/taskinstance.py", line 2212, in render_templates
    rendered_task = self.task.render_template_fields(context)
  File "/home/guilherme/airflow/venv/lib/python3.9/site-packages/airflow/models/baseoperator.py", line 1185, in render_template_fields
    self._do_render_template_fields(self, self.template_fields, context, jinja_env, set())
  File "/home/guilherme/airflow/venv/lib/python3.9/site-packages/airflow/utils/session.py", line 71, in wrapper
    return func(*args, session=session, **kwargs)
  File "/home/guilherme/airflow/venv/lib/python3.9/site-packages/airflow/models/abstractoperator.py", line 344, in _do_render_template_fields
    rendered_content = self.render_template(
  File "/home/guilherme/airflow/venv/lib/python3.9/site-packages/airflow/models/abstractoperator.py", line 387, in render_template
    template = jinja_env.from_string(value)
  File "/home/guilherme/airflow/venv/lib/python3.9/site-packages/jinja2/environment.py", line 1092, in from_string
    return cls.from_code(self, self.compile(source), gs, None)
  File "/home/guilherme/airflow/venv/lib/python3.9/site-packages/jinja2/environment.py", line 757, in compile
    self.handle_exception(source=source_hint)
  File "/home/guilherme/airflow/venv/lib/python3.9/site-packages/jinja2/environment.py", line 925, in handle_exception
    raise rewrite_traceback_stack(source=source)
  File "<unknown>", line 1, in template
jinja2.exceptions.TemplateSyntaxError: unexpected end of template, expected ','.
[2023-08-15 20:00:39,250] {taskinstance.py:1395} INFO - Marking task as FAILED. dag_id=dados_climaticos, task_id=cria_pasta, execution_date=20230424T000000, start_date=20230815T200039, end_date=20230815T200039
[2023-08-15 20:00:39,274] {standard_task_runner.py:92} ERROR - Failed to execute job 53 for task cria_pasta (unexpected end of template, expected ','.; 42584)
[2023-08-15 20:00:39,297] {local_task_job.py:156} INFO - Task exited with return code 1
[2023-08-15 20:00:39,334] {local_task_job.py:273} INFO - 0 downstream tasks scheduled from follow-on schedule check
[2023-08-15 20:04:23,964] {taskinstance.py:1159} INFO - Dependencies all met for <TaskInstance: dados_climaticos.cria_pasta scheduled__2023-04-24T00:00:00+00:00 [queued]>
[2023-08-15 20:04:23,972] {taskinstance.py:1159} INFO - Dependencies all met for <TaskInstance: dados_climaticos.cria_pasta scheduled__2023-04-24T00:00:00+00:00 [queued]>
[2023-08-15 20:04:23,973] {taskinstance.py:1356} INFO - 
--------------------------------------------------------------------------------
[2023-08-15 20:04:23,973] {taskinstance.py:1357} INFO - Starting attempt 1 of 1
[2023-08-15 20:04:23,973] {taskinstance.py:1358} INFO - 
--------------------------------------------------------------------------------
[2023-08-15 20:04:24,004] {taskinstance.py:1377} INFO - Executing <Task(BashOperator): cria_pasta> on 2023-04-24 00:00:00+00:00
[2023-08-15 20:04:24,009] {standard_task_runner.py:52} INFO - Started process 45047 to run task
[2023-08-15 20:04:24,014] {standard_task_runner.py:79} INFO - Running: ['airflow', 'tasks', 'run', 'dados_climaticos', 'cria_pasta', 'scheduled__2023-04-24T00:00:00+00:00', '--job-id', '58', '--raw', '--subdir', 'DAGS_FOLDER/dados_climatics.py', '--cfg-path', '/tmp/tmpxdsvxj4x', '--error-file', '/tmp/tmpp9j7_fi5']
[2023-08-15 20:04:24,014] {standard_task_runner.py:80} INFO - Job 58: Subtask cria_pasta
[2023-08-15 20:04:24,083] {task_command.py:370} INFO - Running <TaskInstance: dados_climaticos.cria_pasta scheduled__2023-04-24T00:00:00+00:00 [running]> on host ubuntu.internal.cloudapp.net
[2023-08-15 20:04:24,121] {taskinstance.py:1889} ERROR - Task failed with exception
Traceback (most recent call last):
  File "/home/guilherme/airflow/venv/lib/python3.9/site-packages/airflow/models/taskinstance.py", line 1451, in _run_raw_task
    self._execute_task_with_callbacks(context, test_mode)
  File "/home/guilherme/airflow/venv/lib/python3.9/site-packages/airflow/models/taskinstance.py", line 1555, in _execute_task_with_callbacks
    task_orig = self.render_templates(context=context)
  File "/home/guilherme/airflow/venv/lib/python3.9/site-packages/airflow/models/taskinstance.py", line 2212, in render_templates
    rendered_task = self.task.render_template_fields(context)
  File "/home/guilherme/airflow/venv/lib/python3.9/site-packages/airflow/models/baseoperator.py", line 1185, in render_template_fields
    self._do_render_template_fields(self, self.template_fields, context, jinja_env, set())
  File "/home/guilherme/airflow/venv/lib/python3.9/site-packages/airflow/utils/session.py", line 71, in wrapper
    return func(*args, session=session, **kwargs)
  File "/home/guilherme/airflow/venv/lib/python3.9/site-packages/airflow/models/abstractoperator.py", line 344, in _do_render_template_fields
    rendered_content = self.render_template(
  File "/home/guilherme/airflow/venv/lib/python3.9/site-packages/airflow/models/abstractoperator.py", line 387, in render_template
    template = jinja_env.from_string(value)
  File "/home/guilherme/airflow/venv/lib/python3.9/site-packages/jinja2/environment.py", line 1092, in from_string
    return cls.from_code(self, self.compile(source), gs, None)
  File "/home/guilherme/airflow/venv/lib/python3.9/site-packages/jinja2/environment.py", line 757, in compile
    self.handle_exception(source=source_hint)
  File "/home/guilherme/airflow/venv/lib/python3.9/site-packages/jinja2/environment.py", line 925, in handle_exception
    raise rewrite_traceback_stack(source=source)
  File "<unknown>", line 1, in template
jinja2.exceptions.TemplateSyntaxError: unexpected end of template, expected ','.
[2023-08-15 20:04:24,125] {taskinstance.py:1395} INFO - Marking task as FAILED. dag_id=dados_climaticos, task_id=cria_pasta, execution_date=20230424T000000, start_date=20230815T200423, end_date=20230815T200424
[2023-08-15 20:04:24,151] {standard_task_runner.py:92} ERROR - Failed to execute job 58 for task cria_pasta (unexpected end of template, expected ','.; 45047)
[2023-08-15 20:04:24,186] {local_task_job.py:156} INFO - Task exited with return code 1
[2023-08-15 20:04:24,226] {local_task_job.py:273} INFO - 0 downstream tasks scheduled from follow-on schedule check
