[2023-08-15 19:59:57,428] {taskinstance.py:1159} INFO - Dependencies all met for <TaskInstance: dados_climaticos.cria_pasta scheduled__2022-12-19T00:00:00+00:00 [queued]>
[2023-08-15 19:59:57,432] {taskinstance.py:1159} INFO - Dependencies all met for <TaskInstance: dados_climaticos.cria_pasta scheduled__2022-12-19T00:00:00+00:00 [queued]>
[2023-08-15 19:59:57,432] {taskinstance.py:1356} INFO - 
--------------------------------------------------------------------------------
[2023-08-15 19:59:57,432] {taskinstance.py:1357} INFO - Starting attempt 1 of 1
[2023-08-15 19:59:57,432] {taskinstance.py:1358} INFO - 
--------------------------------------------------------------------------------
[2023-08-15 19:59:57,455] {taskinstance.py:1377} INFO - Executing <Task(BashOperator): cria_pasta> on 2022-12-19 00:00:00+00:00
[2023-08-15 19:59:57,458] {standard_task_runner.py:52} INFO - Started process 42089 to run task
[2023-08-15 19:59:57,462] {standard_task_runner.py:79} INFO - Running: ['airflow', 'tasks', 'run', 'dados_climaticos', 'cria_pasta', 'scheduled__2022-12-19T00:00:00+00:00', '--job-id', '35', '--raw', '--subdir', 'DAGS_FOLDER/dados_climatics.py', '--cfg-path', '/tmp/tmpo9wtgesb', '--error-file', '/tmp/tmplv__2j4e']
[2023-08-15 19:59:57,463] {standard_task_runner.py:80} INFO - Job 35: Subtask cria_pasta
[2023-08-15 19:59:57,515] {task_command.py:370} INFO - Running <TaskInstance: dados_climaticos.cria_pasta scheduled__2022-12-19T00:00:00+00:00 [running]> on host ubuntu.internal.cloudapp.net
[2023-08-15 19:59:57,554] {taskinstance.py:1889} ERROR - Task failed with exception
Traceback (most recent call last):
  File "/home/guilherme/airflow/venv/lib/python3.9/site-packages/airflow/models/taskinstance.py", line 1451, in _run_raw_task
    self._execute_task_with_callbacks(context, test_mode)
  File "/home/guilherme/airflow/venv/lib/python3.9/site-packages/airflow/models/taskinstance.py", line 1555, in _execute_task_with_callbacks
    task_orig = self.render_templates(context=context)
  File "/home/guilherme/airflow/venv/lib/python3.9/site-packages/airflow/models/taskinstance.py", line 2212, in render_templates
    rendered_task = self.task.render_template_fields(context)
  File "/home/guilherme/airflow/venv/lib/python3.9/site-packages/airflow/models/baseoperator.py", line 1185, in render_template_fields
    self._do_render_template_fields(self, self.template_fields, context, jinja_env, set())
  File "/home/guilherme/airflow/venv/lib/python3.9/site-packages/airflow/utils/session.py", line 71, in wrapper
    return func(*args, session=session, **kwargs)
  File "/home/guilherme/airflow/venv/lib/python3.9/site-packages/airflow/models/abstractoperator.py", line 344, in _do_render_template_fields
    rendered_content = self.render_template(
  File "/home/guilherme/airflow/venv/lib/python3.9/site-packages/airflow/models/abstractoperator.py", line 387, in render_template
    template = jinja_env.from_string(value)
  File "/home/guilherme/airflow/venv/lib/python3.9/site-packages/jinja2/environment.py", line 1092, in from_string
    return cls.from_code(self, self.compile(source), gs, None)
  File "/home/guilherme/airflow/venv/lib/python3.9/site-packages/jinja2/environment.py", line 757, in compile
    self.handle_exception(source=source_hint)
  File "/home/guilherme/airflow/venv/lib/python3.9/site-packages/jinja2/environment.py", line 925, in handle_exception
    raise rewrite_traceback_stack(source=source)
  File "<unknown>", line 1, in template
jinja2.exceptions.TemplateSyntaxError: unexpected end of template, expected ','.
[2023-08-15 19:59:57,558] {taskinstance.py:1395} INFO - Marking task as FAILED. dag_id=dados_climaticos, task_id=cria_pasta, execution_date=20221219T000000, start_date=20230815T195957, end_date=20230815T195957
[2023-08-15 19:59:57,586] {standard_task_runner.py:92} ERROR - Failed to execute job 35 for task cria_pasta (unexpected end of template, expected ','.; 42089)
[2023-08-15 19:59:57,594] {local_task_job.py:156} INFO - Task exited with return code 1
[2023-08-15 19:59:57,632] {local_task_job.py:273} INFO - 0 downstream tasks scheduled from follow-on schedule check
[2023-08-15 20:03:26,272] {taskinstance.py:1159} INFO - Dependencies all met for <TaskInstance: dados_climaticos.cria_pasta scheduled__2022-12-19T00:00:00+00:00 [queued]>
[2023-08-15 20:03:26,277] {taskinstance.py:1159} INFO - Dependencies all met for <TaskInstance: dados_climaticos.cria_pasta scheduled__2022-12-19T00:00:00+00:00 [queued]>
[2023-08-15 20:03:26,278] {taskinstance.py:1356} INFO - 
--------------------------------------------------------------------------------
[2023-08-15 20:03:26,278] {taskinstance.py:1357} INFO - Starting attempt 1 of 1
[2023-08-15 20:03:26,278] {taskinstance.py:1358} INFO - 
--------------------------------------------------------------------------------
[2023-08-15 20:03:26,412] {taskinstance.py:1377} INFO - Executing <Task(BashOperator): cria_pasta> on 2022-12-19 00:00:00+00:00
[2023-08-15 20:03:26,415] {standard_task_runner.py:52} INFO - Started process 44361 to run task
[2023-08-15 20:03:26,419] {standard_task_runner.py:79} INFO - Running: ['airflow', 'tasks', 'run', 'dados_climaticos', 'cria_pasta', 'scheduled__2022-12-19T00:00:00+00:00', '--job-id', '40', '--raw', '--subdir', 'DAGS_FOLDER/dados_climatics.py', '--cfg-path', '/tmp/tmp8xj6ys2e', '--error-file', '/tmp/tmpufzk77sb']
[2023-08-15 20:03:26,420] {standard_task_runner.py:80} INFO - Job 40: Subtask cria_pasta
[2023-08-15 20:03:26,566] {task_command.py:370} INFO - Running <TaskInstance: dados_climaticos.cria_pasta scheduled__2022-12-19T00:00:00+00:00 [running]> on host ubuntu.internal.cloudapp.net
[2023-08-15 20:03:26,660] {taskinstance.py:1889} ERROR - Task failed with exception
Traceback (most recent call last):
  File "/home/guilherme/airflow/venv/lib/python3.9/site-packages/airflow/models/taskinstance.py", line 1451, in _run_raw_task
    self._execute_task_with_callbacks(context, test_mode)
  File "/home/guilherme/airflow/venv/lib/python3.9/site-packages/airflow/models/taskinstance.py", line 1555, in _execute_task_with_callbacks
    task_orig = self.render_templates(context=context)
  File "/home/guilherme/airflow/venv/lib/python3.9/site-packages/airflow/models/taskinstance.py", line 2212, in render_templates
    rendered_task = self.task.render_template_fields(context)
  File "/home/guilherme/airflow/venv/lib/python3.9/site-packages/airflow/models/baseoperator.py", line 1185, in render_template_fields
    self._do_render_template_fields(self, self.template_fields, context, jinja_env, set())
  File "/home/guilherme/airflow/venv/lib/python3.9/site-packages/airflow/utils/session.py", line 71, in wrapper
    return func(*args, session=session, **kwargs)
  File "/home/guilherme/airflow/venv/lib/python3.9/site-packages/airflow/models/abstractoperator.py", line 344, in _do_render_template_fields
    rendered_content = self.render_template(
  File "/home/guilherme/airflow/venv/lib/python3.9/site-packages/airflow/models/abstractoperator.py", line 387, in render_template
    template = jinja_env.from_string(value)
  File "/home/guilherme/airflow/venv/lib/python3.9/site-packages/jinja2/environment.py", line 1092, in from_string
    return cls.from_code(self, self.compile(source), gs, None)
  File "/home/guilherme/airflow/venv/lib/python3.9/site-packages/jinja2/environment.py", line 757, in compile
    self.handle_exception(source=source_hint)
  File "/home/guilherme/airflow/venv/lib/python3.9/site-packages/jinja2/environment.py", line 925, in handle_exception
    raise rewrite_traceback_stack(source=source)
  File "<unknown>", line 1, in template
jinja2.exceptions.TemplateSyntaxError: unexpected end of template, expected ','.
[2023-08-15 20:03:26,664] {taskinstance.py:1395} INFO - Marking task as FAILED. dag_id=dados_climaticos, task_id=cria_pasta, execution_date=20221219T000000, start_date=20230815T200326, end_date=20230815T200326
[2023-08-15 20:03:26,761] {standard_task_runner.py:92} ERROR - Failed to execute job 40 for task cria_pasta (unexpected end of template, expected ','.; 44361)
[2023-08-15 20:03:26,792] {local_task_job.py:156} INFO - Task exited with return code 1
[2023-08-15 20:03:26,912] {local_task_job.py:273} INFO - 0 downstream tasks scheduled from follow-on schedule check
