[2023-08-15 20:09:12,213] {taskinstance.py:1159} INFO - Dependencies all met for <TaskInstance: dados_climaticos.cria_pasta_mes_ano scheduled__2023-01-09T00:00:00+00:00 [queued]>
[2023-08-15 20:09:12,218] {taskinstance.py:1159} INFO - Dependencies all met for <TaskInstance: dados_climaticos.cria_pasta_mes_ano scheduled__2023-01-09T00:00:00+00:00 [queued]>
[2023-08-15 20:09:12,218] {taskinstance.py:1356} INFO - 
--------------------------------------------------------------------------------
[2023-08-15 20:09:12,218] {taskinstance.py:1357} INFO - Starting attempt 1 of 1
[2023-08-15 20:09:12,218] {taskinstance.py:1358} INFO - 
--------------------------------------------------------------------------------
[2023-08-15 20:09:12,244] {taskinstance.py:1377} INFO - Executing <Task(BashOperator): cria_pasta_mes_ano> on 2023-01-09 00:00:00+00:00
[2023-08-15 20:09:12,247] {standard_task_runner.py:52} INFO - Started process 47084 to run task
[2023-08-15 20:09:12,252] {standard_task_runner.py:79} INFO - Running: ['airflow', 'tasks', 'run', 'dados_climaticos', 'cria_pasta_mes_ano', 'scheduled__2023-01-09T00:00:00+00:00', '--job-id', '98', '--raw', '--subdir', 'DAGS_FOLDER/dados_climatics.py', '--cfg-path', '/tmp/tmpe95ixcb3', '--error-file', '/tmp/tmpt6dr1kz2']
[2023-08-15 20:09:12,253] {standard_task_runner.py:80} INFO - Job 98: Subtask cria_pasta_mes_ano
[2023-08-15 20:09:12,312] {task_command.py:370} INFO - Running <TaskInstance: dados_climaticos.cria_pasta_mes_ano scheduled__2023-01-09T00:00:00+00:00 [running]> on host ubuntu.internal.cloudapp.net
[2023-08-15 20:09:12,349] {taskinstance.py:1889} ERROR - Task failed with exception
Traceback (most recent call last):
  File "/home/guilherme/airflow/venv/lib/python3.9/site-packages/airflow/models/taskinstance.py", line 1451, in _run_raw_task
    self._execute_task_with_callbacks(context, test_mode)
  File "/home/guilherme/airflow/venv/lib/python3.9/site-packages/airflow/models/taskinstance.py", line 1555, in _execute_task_with_callbacks
    task_orig = self.render_templates(context=context)
  File "/home/guilherme/airflow/venv/lib/python3.9/site-packages/airflow/models/taskinstance.py", line 2212, in render_templates
    rendered_task = self.task.render_template_fields(context)
  File "/home/guilherme/airflow/venv/lib/python3.9/site-packages/airflow/models/baseoperator.py", line 1185, in render_template_fields
    self._do_render_template_fields(self, self.template_fields, context, jinja_env, set())
  File "/home/guilherme/airflow/venv/lib/python3.9/site-packages/airflow/utils/session.py", line 71, in wrapper
    return func(*args, session=session, **kwargs)
  File "/home/guilherme/airflow/venv/lib/python3.9/site-packages/airflow/models/abstractoperator.py", line 344, in _do_render_template_fields
    rendered_content = self.render_template(
  File "/home/guilherme/airflow/venv/lib/python3.9/site-packages/airflow/models/abstractoperator.py", line 387, in render_template
    template = jinja_env.from_string(value)
  File "/home/guilherme/airflow/venv/lib/python3.9/site-packages/jinja2/environment.py", line 1092, in from_string
    return cls.from_code(self, self.compile(source), gs, None)
  File "/home/guilherme/airflow/venv/lib/python3.9/site-packages/jinja2/environment.py", line 757, in compile
    self.handle_exception(source=source_hint)
  File "/home/guilherme/airflow/venv/lib/python3.9/site-packages/jinja2/environment.py", line 925, in handle_exception
    raise rewrite_traceback_stack(source=source)
  File "<unknown>", line 1, in template
jinja2.exceptions.TemplateSyntaxError: unexpected end of template, expected ','.
[2023-08-15 20:09:12,353] {taskinstance.py:1395} INFO - Marking task as FAILED. dag_id=dados_climaticos, task_id=cria_pasta_mes_ano, execution_date=20230109T000000, start_date=20230815T200912, end_date=20230815T200912
[2023-08-15 20:09:12,377] {standard_task_runner.py:92} ERROR - Failed to execute job 98 for task cria_pasta_mes_ano (unexpected end of template, expected ','.; 47084)
[2023-08-15 20:09:12,388] {local_task_job.py:156} INFO - Task exited with return code 1
[2023-08-15 20:09:12,430] {local_task_job.py:273} INFO - 0 downstream tasks scheduled from follow-on schedule check
[2023-08-15 20:27:29,628] {taskinstance.py:1159} INFO - Dependencies all met for <TaskInstance: dados_climaticos.cria_pasta_mes_ano scheduled__2023-01-09T00:00:00+00:00 [queued]>
[2023-08-15 20:27:29,633] {taskinstance.py:1159} INFO - Dependencies all met for <TaskInstance: dados_climaticos.cria_pasta_mes_ano scheduled__2023-01-09T00:00:00+00:00 [queued]>
[2023-08-15 20:27:29,633] {taskinstance.py:1356} INFO - 
--------------------------------------------------------------------------------
[2023-08-15 20:27:29,633] {taskinstance.py:1357} INFO - Starting attempt 1 of 1
[2023-08-15 20:27:29,633] {taskinstance.py:1358} INFO - 
--------------------------------------------------------------------------------
[2023-08-15 20:27:29,655] {taskinstance.py:1377} INFO - Executing <Task(BashOperator): cria_pasta_mes_ano> on 2023-01-09 00:00:00+00:00
[2023-08-15 20:27:29,658] {standard_task_runner.py:52} INFO - Started process 50660 to run task
[2023-08-15 20:27:29,663] {standard_task_runner.py:79} INFO - Running: ['airflow', 'tasks', 'run', 'dados_climaticos', 'cria_pasta_mes_ano', 'scheduled__2023-01-09T00:00:00+00:00', '--job-id', '134', '--raw', '--subdir', 'DAGS_FOLDER/dados_climatics.py', '--cfg-path', '/tmp/tmphywzd7eq', '--error-file', '/tmp/tmp7q0zs2i2']
[2023-08-15 20:27:29,663] {standard_task_runner.py:80} INFO - Job 134: Subtask cria_pasta_mes_ano
[2023-08-15 20:27:29,714] {task_command.py:370} INFO - Running <TaskInstance: dados_climaticos.cria_pasta_mes_ano scheduled__2023-01-09T00:00:00+00:00 [running]> on host ubuntu.internal.cloudapp.net
[2023-08-15 20:27:29,780] {taskinstance.py:1569} INFO - Exporting the following env vars:
AIRFLOW_CTX_DAG_OWNER=airflow
AIRFLOW_CTX_DAG_ID=dados_climaticos
AIRFLOW_CTX_TASK_ID=cria_pasta_mes_ano
AIRFLOW_CTX_EXECUTION_DATE=2023-01-09T00:00:00+00:00
AIRFLOW_CTX_TRY_NUMBER=1
AIRFLOW_CTX_DAG_RUN_ID=scheduled__2023-01-09T00:00:00+00:00
[2023-08-15 20:27:29,781] {subprocess.py:62} INFO - Tmp dir root location: 
 /tmp
[2023-08-15 20:27:29,782] {subprocess.py:74} INFO - Running command: ['bash', '-c', 'mkdir -p "/home/guilherme/airflow/semana=2023-01"']
[2023-08-15 20:27:29,791] {subprocess.py:85} INFO - Output:
[2023-08-15 20:27:29,793] {subprocess.py:96} INFO - Command exited with return code 0
[2023-08-15 20:27:29,823] {taskinstance.py:1395} INFO - Marking task as SUCCESS. dag_id=dados_climaticos, task_id=cria_pasta_mes_ano, execution_date=20230109T000000, start_date=20230815T202729, end_date=20230815T202729
[2023-08-15 20:27:29,875] {local_task_job.py:156} INFO - Task exited with return code 0
[2023-08-15 20:27:29,910] {local_task_job.py:273} INFO - 1 downstream tasks scheduled from follow-on schedule check
[2023-08-15 20:39:12,404] {taskinstance.py:1159} INFO - Dependencies all met for <TaskInstance: dados_climaticos.cria_pasta_mes_ano scheduled__2023-01-09T00:00:00+00:00 [queued]>
[2023-08-15 20:39:12,411] {taskinstance.py:1159} INFO - Dependencies all met for <TaskInstance: dados_climaticos.cria_pasta_mes_ano scheduled__2023-01-09T00:00:00+00:00 [queued]>
[2023-08-15 20:39:12,411] {taskinstance.py:1356} INFO - 
--------------------------------------------------------------------------------
[2023-08-15 20:39:12,411] {taskinstance.py:1357} INFO - Starting attempt 1 of 1
[2023-08-15 20:39:12,411] {taskinstance.py:1358} INFO - 
--------------------------------------------------------------------------------
[2023-08-15 20:39:12,434] {taskinstance.py:1377} INFO - Executing <Task(BashOperator): cria_pasta_mes_ano> on 2023-01-09 00:00:00+00:00
[2023-08-15 20:39:12,438] {standard_task_runner.py:52} INFO - Started process 55646 to run task
[2023-08-15 20:39:12,443] {standard_task_runner.py:79} INFO - Running: ['airflow', 'tasks', 'run', 'dados_climaticos', 'cria_pasta_mes_ano', 'scheduled__2023-01-09T00:00:00+00:00', '--job-id', '235', '--raw', '--subdir', 'DAGS_FOLDER/dados_climatics.py', '--cfg-path', '/tmp/tmpwjwfcn02', '--error-file', '/tmp/tmprv0m80ea']
[2023-08-15 20:39:12,444] {standard_task_runner.py:80} INFO - Job 235: Subtask cria_pasta_mes_ano
[2023-08-15 20:39:12,498] {task_command.py:370} INFO - Running <TaskInstance: dados_climaticos.cria_pasta_mes_ano scheduled__2023-01-09T00:00:00+00:00 [running]> on host ubuntu.internal.cloudapp.net
[2023-08-15 20:39:12,568] {taskinstance.py:1569} INFO - Exporting the following env vars:
AIRFLOW_CTX_DAG_OWNER=airflow
AIRFLOW_CTX_DAG_ID=dados_climaticos
AIRFLOW_CTX_TASK_ID=cria_pasta_mes_ano
AIRFLOW_CTX_EXECUTION_DATE=2023-01-09T00:00:00+00:00
AIRFLOW_CTX_TRY_NUMBER=1
AIRFLOW_CTX_DAG_RUN_ID=scheduled__2023-01-09T00:00:00+00:00
[2023-08-15 20:39:12,569] {subprocess.py:62} INFO - Tmp dir root location: 
 /tmp
[2023-08-15 20:39:12,569] {subprocess.py:74} INFO - Running command: ['bash', '-c', 'mkdir -p "/home/guilherme/airflow/dados/semana=2023-01"']
[2023-08-15 20:39:12,577] {subprocess.py:85} INFO - Output:
[2023-08-15 20:39:12,580] {subprocess.py:96} INFO - Command exited with return code 0
[2023-08-15 20:39:12,613] {taskinstance.py:1395} INFO - Marking task as SUCCESS. dag_id=dados_climaticos, task_id=cria_pasta_mes_ano, execution_date=20230109T000000, start_date=20230815T203912, end_date=20230815T203912
[2023-08-15 20:39:12,655] {local_task_job.py:156} INFO - Task exited with return code 0
[2023-08-15 20:39:12,696] {local_task_job.py:273} INFO - 1 downstream tasks scheduled from follow-on schedule check
