[2023-08-15 20:09:08,892] {taskinstance.py:1159} INFO - Dependencies all met for <TaskInstance: dados_climaticos.cria_pasta_mes_ano scheduled__2023-01-02T00:00:00+00:00 [queued]>
[2023-08-15 20:09:08,898] {taskinstance.py:1159} INFO - Dependencies all met for <TaskInstance: dados_climaticos.cria_pasta_mes_ano scheduled__2023-01-02T00:00:00+00:00 [queued]>
[2023-08-15 20:09:08,898] {taskinstance.py:1356} INFO - 
--------------------------------------------------------------------------------
[2023-08-15 20:09:08,898] {taskinstance.py:1357} INFO - Starting attempt 1 of 1
[2023-08-15 20:09:08,898] {taskinstance.py:1358} INFO - 
--------------------------------------------------------------------------------
[2023-08-15 20:09:08,925] {taskinstance.py:1377} INFO - Executing <Task(BashOperator): cria_pasta_mes_ano> on 2023-01-02 00:00:00+00:00
[2023-08-15 20:09:08,928] {standard_task_runner.py:52} INFO - Started process 47025 to run task
[2023-08-15 20:09:08,933] {standard_task_runner.py:79} INFO - Running: ['airflow', 'tasks', 'run', 'dados_climaticos', 'cria_pasta_mes_ano', 'scheduled__2023-01-02T00:00:00+00:00', '--job-id', '97', '--raw', '--subdir', 'DAGS_FOLDER/dados_climatics.py', '--cfg-path', '/tmp/tmpnmrczze_', '--error-file', '/tmp/tmpnrbo5lj6']
[2023-08-15 20:09:08,934] {standard_task_runner.py:80} INFO - Job 97: Subtask cria_pasta_mes_ano
[2023-08-15 20:09:08,985] {task_command.py:370} INFO - Running <TaskInstance: dados_climaticos.cria_pasta_mes_ano scheduled__2023-01-02T00:00:00+00:00 [running]> on host ubuntu.internal.cloudapp.net
[2023-08-15 20:09:09,020] {taskinstance.py:1889} ERROR - Task failed with exception
Traceback (most recent call last):
  File "/home/guilherme/airflow/venv/lib/python3.9/site-packages/airflow/models/taskinstance.py", line 1451, in _run_raw_task
    self._execute_task_with_callbacks(context, test_mode)
  File "/home/guilherme/airflow/venv/lib/python3.9/site-packages/airflow/models/taskinstance.py", line 1555, in _execute_task_with_callbacks
    task_orig = self.render_templates(context=context)
  File "/home/guilherme/airflow/venv/lib/python3.9/site-packages/airflow/models/taskinstance.py", line 2212, in render_templates
    rendered_task = self.task.render_template_fields(context)
  File "/home/guilherme/airflow/venv/lib/python3.9/site-packages/airflow/models/baseoperator.py", line 1185, in render_template_fields
    self._do_render_template_fields(self, self.template_fields, context, jinja_env, set())
  File "/home/guilherme/airflow/venv/lib/python3.9/site-packages/airflow/utils/session.py", line 71, in wrapper
    return func(*args, session=session, **kwargs)
  File "/home/guilherme/airflow/venv/lib/python3.9/site-packages/airflow/models/abstractoperator.py", line 344, in _do_render_template_fields
    rendered_content = self.render_template(
  File "/home/guilherme/airflow/venv/lib/python3.9/site-packages/airflow/models/abstractoperator.py", line 387, in render_template
    template = jinja_env.from_string(value)
  File "/home/guilherme/airflow/venv/lib/python3.9/site-packages/jinja2/environment.py", line 1092, in from_string
    return cls.from_code(self, self.compile(source), gs, None)
  File "/home/guilherme/airflow/venv/lib/python3.9/site-packages/jinja2/environment.py", line 757, in compile
    self.handle_exception(source=source_hint)
  File "/home/guilherme/airflow/venv/lib/python3.9/site-packages/jinja2/environment.py", line 925, in handle_exception
    raise rewrite_traceback_stack(source=source)
  File "<unknown>", line 1, in template
jinja2.exceptions.TemplateSyntaxError: unexpected end of template, expected ','.
[2023-08-15 20:09:09,025] {taskinstance.py:1395} INFO - Marking task as FAILED. dag_id=dados_climaticos, task_id=cria_pasta_mes_ano, execution_date=20230102T000000, start_date=20230815T200908, end_date=20230815T200909
[2023-08-15 20:09:09,045] {standard_task_runner.py:92} ERROR - Failed to execute job 97 for task cria_pasta_mes_ano (unexpected end of template, expected ','.; 47025)
[2023-08-15 20:09:09,065] {local_task_job.py:156} INFO - Task exited with return code 1
[2023-08-15 20:09:09,102] {local_task_job.py:273} INFO - 0 downstream tasks scheduled from follow-on schedule check
[2023-08-15 20:27:25,839] {taskinstance.py:1159} INFO - Dependencies all met for <TaskInstance: dados_climaticos.cria_pasta_mes_ano scheduled__2023-01-02T00:00:00+00:00 [queued]>
[2023-08-15 20:27:25,845] {taskinstance.py:1159} INFO - Dependencies all met for <TaskInstance: dados_climaticos.cria_pasta_mes_ano scheduled__2023-01-02T00:00:00+00:00 [queued]>
[2023-08-15 20:27:25,845] {taskinstance.py:1356} INFO - 
--------------------------------------------------------------------------------
[2023-08-15 20:27:25,845] {taskinstance.py:1357} INFO - Starting attempt 1 of 1
[2023-08-15 20:27:25,845] {taskinstance.py:1358} INFO - 
--------------------------------------------------------------------------------
[2023-08-15 20:27:25,870] {taskinstance.py:1377} INFO - Executing <Task(BashOperator): cria_pasta_mes_ano> on 2023-01-02 00:00:00+00:00
[2023-08-15 20:27:25,873] {standard_task_runner.py:52} INFO - Started process 50598 to run task
[2023-08-15 20:27:25,877] {standard_task_runner.py:79} INFO - Running: ['airflow', 'tasks', 'run', 'dados_climaticos', 'cria_pasta_mes_ano', 'scheduled__2023-01-02T00:00:00+00:00', '--job-id', '132', '--raw', '--subdir', 'DAGS_FOLDER/dados_climatics.py', '--cfg-path', '/tmp/tmpx3aqw6kt', '--error-file', '/tmp/tmpiysjy0n7']
[2023-08-15 20:27:25,878] {standard_task_runner.py:80} INFO - Job 132: Subtask cria_pasta_mes_ano
[2023-08-15 20:27:25,927] {task_command.py:370} INFO - Running <TaskInstance: dados_climaticos.cria_pasta_mes_ano scheduled__2023-01-02T00:00:00+00:00 [running]> on host ubuntu.internal.cloudapp.net
[2023-08-15 20:27:25,993] {taskinstance.py:1569} INFO - Exporting the following env vars:
AIRFLOW_CTX_DAG_OWNER=airflow
AIRFLOW_CTX_DAG_ID=dados_climaticos
AIRFLOW_CTX_TASK_ID=cria_pasta_mes_ano
AIRFLOW_CTX_EXECUTION_DATE=2023-01-02T00:00:00+00:00
AIRFLOW_CTX_TRY_NUMBER=1
AIRFLOW_CTX_DAG_RUN_ID=scheduled__2023-01-02T00:00:00+00:00
[2023-08-15 20:27:25,994] {subprocess.py:62} INFO - Tmp dir root location: 
 /tmp
[2023-08-15 20:27:25,994] {subprocess.py:74} INFO - Running command: ['bash', '-c', 'mkdir -p "/home/guilherme/airflow/semana=2023-01"']
[2023-08-15 20:27:26,002] {subprocess.py:85} INFO - Output:
[2023-08-15 20:27:26,004] {subprocess.py:96} INFO - Command exited with return code 0
[2023-08-15 20:27:26,048] {taskinstance.py:1395} INFO - Marking task as SUCCESS. dag_id=dados_climaticos, task_id=cria_pasta_mes_ano, execution_date=20230102T000000, start_date=20230815T202725, end_date=20230815T202726
[2023-08-15 20:27:26,089] {local_task_job.py:156} INFO - Task exited with return code 0
[2023-08-15 20:27:26,146] {local_task_job.py:273} INFO - 1 downstream tasks scheduled from follow-on schedule check
[2023-08-15 20:39:07,914] {taskinstance.py:1159} INFO - Dependencies all met for <TaskInstance: dados_climaticos.cria_pasta_mes_ano scheduled__2023-01-02T00:00:00+00:00 [queued]>
[2023-08-15 20:39:07,920] {taskinstance.py:1159} INFO - Dependencies all met for <TaskInstance: dados_climaticos.cria_pasta_mes_ano scheduled__2023-01-02T00:00:00+00:00 [queued]>
[2023-08-15 20:39:07,920] {taskinstance.py:1356} INFO - 
--------------------------------------------------------------------------------
[2023-08-15 20:39:07,920] {taskinstance.py:1357} INFO - Starting attempt 1 of 1
[2023-08-15 20:39:07,920] {taskinstance.py:1358} INFO - 
--------------------------------------------------------------------------------
[2023-08-15 20:39:07,945] {taskinstance.py:1377} INFO - Executing <Task(BashOperator): cria_pasta_mes_ano> on 2023-01-02 00:00:00+00:00
[2023-08-15 20:39:07,948] {standard_task_runner.py:52} INFO - Started process 55586 to run task
[2023-08-15 20:39:07,954] {standard_task_runner.py:79} INFO - Running: ['airflow', 'tasks', 'run', 'dados_climaticos', 'cria_pasta_mes_ano', 'scheduled__2023-01-02T00:00:00+00:00', '--job-id', '233', '--raw', '--subdir', 'DAGS_FOLDER/dados_climatics.py', '--cfg-path', '/tmp/tmphgjbm8h0', '--error-file', '/tmp/tmp95lhlrtl']
[2023-08-15 20:39:07,955] {standard_task_runner.py:80} INFO - Job 233: Subtask cria_pasta_mes_ano
[2023-08-15 20:39:08,009] {task_command.py:370} INFO - Running <TaskInstance: dados_climaticos.cria_pasta_mes_ano scheduled__2023-01-02T00:00:00+00:00 [running]> on host ubuntu.internal.cloudapp.net
[2023-08-15 20:39:08,097] {taskinstance.py:1569} INFO - Exporting the following env vars:
AIRFLOW_CTX_DAG_OWNER=airflow
AIRFLOW_CTX_DAG_ID=dados_climaticos
AIRFLOW_CTX_TASK_ID=cria_pasta_mes_ano
AIRFLOW_CTX_EXECUTION_DATE=2023-01-02T00:00:00+00:00
AIRFLOW_CTX_TRY_NUMBER=1
AIRFLOW_CTX_DAG_RUN_ID=scheduled__2023-01-02T00:00:00+00:00
[2023-08-15 20:39:08,098] {subprocess.py:62} INFO - Tmp dir root location: 
 /tmp
[2023-08-15 20:39:08,099] {subprocess.py:74} INFO - Running command: ['bash', '-c', 'mkdir -p "/home/guilherme/airflow/dados/semana=2023-01"']
[2023-08-15 20:39:08,107] {subprocess.py:85} INFO - Output:
[2023-08-15 20:39:08,109] {subprocess.py:96} INFO - Command exited with return code 0
[2023-08-15 20:39:08,150] {taskinstance.py:1395} INFO - Marking task as SUCCESS. dag_id=dados_climaticos, task_id=cria_pasta_mes_ano, execution_date=20230102T000000, start_date=20230815T203907, end_date=20230815T203908
[2023-08-15 20:39:08,206] {local_task_job.py:156} INFO - Task exited with return code 0
[2023-08-15 20:39:08,255] {local_task_job.py:273} INFO - 1 downstream tasks scheduled from follow-on schedule check
