[2023-08-15 20:09:38,440] {taskinstance.py:1159} INFO - Dependencies all met for <TaskInstance: dados_climaticos.cria_pasta_mes_ano scheduled__2023-03-20T00:00:00+00:00 [queued]>
[2023-08-15 20:09:38,445] {taskinstance.py:1159} INFO - Dependencies all met for <TaskInstance: dados_climaticos.cria_pasta_mes_ano scheduled__2023-03-20T00:00:00+00:00 [queued]>
[2023-08-15 20:09:38,445] {taskinstance.py:1356} INFO - 
--------------------------------------------------------------------------------
[2023-08-15 20:09:38,445] {taskinstance.py:1357} INFO - Starting attempt 1 of 1
[2023-08-15 20:09:38,445] {taskinstance.py:1358} INFO - 
--------------------------------------------------------------------------------
[2023-08-15 20:09:38,470] {taskinstance.py:1377} INFO - Executing <Task(BashOperator): cria_pasta_mes_ano> on 2023-03-20 00:00:00+00:00
[2023-08-15 20:09:38,474] {standard_task_runner.py:52} INFO - Started process 47384 to run task
[2023-08-15 20:09:38,478] {standard_task_runner.py:79} INFO - Running: ['airflow', 'tasks', 'run', 'dados_climaticos', 'cria_pasta_mes_ano', 'scheduled__2023-03-20T00:00:00+00:00', '--job-id', '108', '--raw', '--subdir', 'DAGS_FOLDER/dados_climatics.py', '--cfg-path', '/tmp/tmphkjq490h', '--error-file', '/tmp/tmpgrre0kjy']
[2023-08-15 20:09:38,479] {standard_task_runner.py:80} INFO - Job 108: Subtask cria_pasta_mes_ano
[2023-08-15 20:09:38,539] {task_command.py:370} INFO - Running <TaskInstance: dados_climaticos.cria_pasta_mes_ano scheduled__2023-03-20T00:00:00+00:00 [running]> on host ubuntu.internal.cloudapp.net
[2023-08-15 20:09:38,578] {taskinstance.py:1889} ERROR - Task failed with exception
Traceback (most recent call last):
  File "/home/guilherme/airflow/venv/lib/python3.9/site-packages/airflow/models/taskinstance.py", line 1451, in _run_raw_task
    self._execute_task_with_callbacks(context, test_mode)
  File "/home/guilherme/airflow/venv/lib/python3.9/site-packages/airflow/models/taskinstance.py", line 1555, in _execute_task_with_callbacks
    task_orig = self.render_templates(context=context)
  File "/home/guilherme/airflow/venv/lib/python3.9/site-packages/airflow/models/taskinstance.py", line 2212, in render_templates
    rendered_task = self.task.render_template_fields(context)
  File "/home/guilherme/airflow/venv/lib/python3.9/site-packages/airflow/models/baseoperator.py", line 1185, in render_template_fields
    self._do_render_template_fields(self, self.template_fields, context, jinja_env, set())
  File "/home/guilherme/airflow/venv/lib/python3.9/site-packages/airflow/utils/session.py", line 71, in wrapper
    return func(*args, session=session, **kwargs)
  File "/home/guilherme/airflow/venv/lib/python3.9/site-packages/airflow/models/abstractoperator.py", line 344, in _do_render_template_fields
    rendered_content = self.render_template(
  File "/home/guilherme/airflow/venv/lib/python3.9/site-packages/airflow/models/abstractoperator.py", line 387, in render_template
    template = jinja_env.from_string(value)
  File "/home/guilherme/airflow/venv/lib/python3.9/site-packages/jinja2/environment.py", line 1092, in from_string
    return cls.from_code(self, self.compile(source), gs, None)
  File "/home/guilherme/airflow/venv/lib/python3.9/site-packages/jinja2/environment.py", line 757, in compile
    self.handle_exception(source=source_hint)
  File "/home/guilherme/airflow/venv/lib/python3.9/site-packages/jinja2/environment.py", line 925, in handle_exception
    raise rewrite_traceback_stack(source=source)
  File "<unknown>", line 1, in template
jinja2.exceptions.TemplateSyntaxError: unexpected end of template, expected ','.
[2023-08-15 20:09:38,583] {taskinstance.py:1395} INFO - Marking task as FAILED. dag_id=dados_climaticos, task_id=cria_pasta_mes_ano, execution_date=20230320T000000, start_date=20230815T200938, end_date=20230815T200938
[2023-08-15 20:09:38,617] {standard_task_runner.py:92} ERROR - Failed to execute job 108 for task cria_pasta_mes_ano (unexpected end of template, expected ','.; 47384)
[2023-08-15 20:09:38,650] {local_task_job.py:156} INFO - Task exited with return code 1
[2023-08-15 20:09:38,689] {local_task_job.py:273} INFO - 0 downstream tasks scheduled from follow-on schedule check
[2023-08-15 20:29:13,217] {taskinstance.py:1159} INFO - Dependencies all met for <TaskInstance: dados_climaticos.cria_pasta_mes_ano scheduled__2023-03-20T00:00:00+00:00 [queued]>
[2023-08-15 20:29:13,222] {taskinstance.py:1159} INFO - Dependencies all met for <TaskInstance: dados_climaticos.cria_pasta_mes_ano scheduled__2023-03-20T00:00:00+00:00 [queued]>
[2023-08-15 20:29:13,222] {taskinstance.py:1356} INFO - 
--------------------------------------------------------------------------------
[2023-08-15 20:29:13,222] {taskinstance.py:1357} INFO - Starting attempt 1 of 1
[2023-08-15 20:29:13,222] {taskinstance.py:1358} INFO - 
--------------------------------------------------------------------------------
[2023-08-15 20:29:13,244] {taskinstance.py:1377} INFO - Executing <Task(BashOperator): cria_pasta_mes_ano> on 2023-03-20 00:00:00+00:00
[2023-08-15 20:29:13,248] {standard_task_runner.py:52} INFO - Started process 51713 to run task
[2023-08-15 20:29:13,252] {standard_task_runner.py:79} INFO - Running: ['airflow', 'tasks', 'run', 'dados_climaticos', 'cria_pasta_mes_ano', 'scheduled__2023-03-20T00:00:00+00:00', '--job-id', '167', '--raw', '--subdir', 'DAGS_FOLDER/dados_climatics.py', '--cfg-path', '/tmp/tmp02fhsytp', '--error-file', '/tmp/tmptcwtygbj']
[2023-08-15 20:29:13,253] {standard_task_runner.py:80} INFO - Job 167: Subtask cria_pasta_mes_ano
[2023-08-15 20:29:13,308] {task_command.py:370} INFO - Running <TaskInstance: dados_climaticos.cria_pasta_mes_ano scheduled__2023-03-20T00:00:00+00:00 [running]> on host ubuntu.internal.cloudapp.net
[2023-08-15 20:29:13,386] {taskinstance.py:1569} INFO - Exporting the following env vars:
AIRFLOW_CTX_DAG_OWNER=airflow
AIRFLOW_CTX_DAG_ID=dados_climaticos
AIRFLOW_CTX_TASK_ID=cria_pasta_mes_ano
AIRFLOW_CTX_EXECUTION_DATE=2023-03-20T00:00:00+00:00
AIRFLOW_CTX_TRY_NUMBER=1
AIRFLOW_CTX_DAG_RUN_ID=scheduled__2023-03-20T00:00:00+00:00
[2023-08-15 20:29:13,388] {subprocess.py:62} INFO - Tmp dir root location: 
 /tmp
[2023-08-15 20:29:13,388] {subprocess.py:74} INFO - Running command: ['bash', '-c', 'mkdir -p "/home/guilherme/airflow/semana=2023-03"']
[2023-08-15 20:29:13,394] {subprocess.py:85} INFO - Output:
[2023-08-15 20:29:13,397] {subprocess.py:96} INFO - Command exited with return code 0
[2023-08-15 20:29:13,426] {taskinstance.py:1395} INFO - Marking task as SUCCESS. dag_id=dados_climaticos, task_id=cria_pasta_mes_ano, execution_date=20230320T000000, start_date=20230815T202913, end_date=20230815T202913
[2023-08-15 20:29:13,464] {local_task_job.py:156} INFO - Task exited with return code 0
[2023-08-15 20:29:13,499] {local_task_job.py:273} INFO - 1 downstream tasks scheduled from follow-on schedule check
[2023-08-15 20:43:40,060] {taskinstance.py:1159} INFO - Dependencies all met for <TaskInstance: dados_climaticos.cria_pasta_mes_ano scheduled__2023-03-20T00:00:00+00:00 [queued]>
[2023-08-15 20:43:40,066] {taskinstance.py:1159} INFO - Dependencies all met for <TaskInstance: dados_climaticos.cria_pasta_mes_ano scheduled__2023-03-20T00:00:00+00:00 [queued]>
[2023-08-15 20:43:40,066] {taskinstance.py:1356} INFO - 
--------------------------------------------------------------------------------
[2023-08-15 20:43:40,066] {taskinstance.py:1357} INFO - Starting attempt 1 of 1
[2023-08-15 20:43:40,066] {taskinstance.py:1358} INFO - 
--------------------------------------------------------------------------------
[2023-08-15 20:43:40,089] {taskinstance.py:1377} INFO - Executing <Task(BashOperator): cria_pasta_mes_ano> on 2023-03-20 00:00:00+00:00
[2023-08-15 20:43:40,093] {standard_task_runner.py:52} INFO - Started process 56786 to run task
[2023-08-15 20:43:40,098] {standard_task_runner.py:79} INFO - Running: ['airflow', 'tasks', 'run', 'dados_climaticos', 'cria_pasta_mes_ano', 'scheduled__2023-03-20T00:00:00+00:00', '--job-id', '267', '--raw', '--subdir', 'DAGS_FOLDER/dados_climatics.py', '--cfg-path', '/tmp/tmph4i6e4b8', '--error-file', '/tmp/tmpu9u4xwll']
[2023-08-15 20:43:40,099] {standard_task_runner.py:80} INFO - Job 267: Subtask cria_pasta_mes_ano
[2023-08-15 20:43:40,161] {task_command.py:370} INFO - Running <TaskInstance: dados_climaticos.cria_pasta_mes_ano scheduled__2023-03-20T00:00:00+00:00 [running]> on host ubuntu.internal.cloudapp.net
[2023-08-15 20:43:40,230] {taskinstance.py:1569} INFO - Exporting the following env vars:
AIRFLOW_CTX_DAG_OWNER=airflow
AIRFLOW_CTX_DAG_ID=dados_climaticos
AIRFLOW_CTX_TASK_ID=cria_pasta_mes_ano
AIRFLOW_CTX_EXECUTION_DATE=2023-03-20T00:00:00+00:00
AIRFLOW_CTX_TRY_NUMBER=1
AIRFLOW_CTX_DAG_RUN_ID=scheduled__2023-03-20T00:00:00+00:00
[2023-08-15 20:43:40,232] {subprocess.py:62} INFO - Tmp dir root location: 
 /tmp
[2023-08-15 20:43:40,232] {subprocess.py:74} INFO - Running command: ['bash', '-c', 'mkdir -p "/home/guilherme/airflow/dados/semana=2023-03"']
[2023-08-15 20:43:40,239] {subprocess.py:85} INFO - Output:
[2023-08-15 20:43:40,242] {subprocess.py:96} INFO - Command exited with return code 0
[2023-08-15 20:43:40,275] {taskinstance.py:1395} INFO - Marking task as SUCCESS. dag_id=dados_climaticos, task_id=cria_pasta_mes_ano, execution_date=20230320T000000, start_date=20230815T204340, end_date=20230815T204340
[2023-08-15 20:43:40,310] {local_task_job.py:156} INFO - Task exited with return code 0
[2023-08-15 20:43:40,348] {local_task_job.py:273} INFO - 1 downstream tasks scheduled from follow-on schedule check
