[2023-08-15 20:09:17,458] {taskinstance.py:1159} INFO - Dependencies all met for <TaskInstance: dados_climaticos.cria_pasta_mes_ano scheduled__2023-01-23T00:00:00+00:00 [queued]>
[2023-08-15 20:09:17,463] {taskinstance.py:1159} INFO - Dependencies all met for <TaskInstance: dados_climaticos.cria_pasta_mes_ano scheduled__2023-01-23T00:00:00+00:00 [queued]>
[2023-08-15 20:09:17,463] {taskinstance.py:1356} INFO - 
--------------------------------------------------------------------------------
[2023-08-15 20:09:17,463] {taskinstance.py:1357} INFO - Starting attempt 1 of 1
[2023-08-15 20:09:17,463] {taskinstance.py:1358} INFO - 
--------------------------------------------------------------------------------
[2023-08-15 20:09:17,492] {taskinstance.py:1377} INFO - Executing <Task(BashOperator): cria_pasta_mes_ano> on 2023-01-23 00:00:00+00:00
[2023-08-15 20:09:17,495] {standard_task_runner.py:52} INFO - Started process 47144 to run task
[2023-08-15 20:09:17,501] {standard_task_runner.py:79} INFO - Running: ['airflow', 'tasks', 'run', 'dados_climaticos', 'cria_pasta_mes_ano', 'scheduled__2023-01-23T00:00:00+00:00', '--job-id', '100', '--raw', '--subdir', 'DAGS_FOLDER/dados_climatics.py', '--cfg-path', '/tmp/tmp48fny98u', '--error-file', '/tmp/tmpjexo49k4']
[2023-08-15 20:09:17,502] {standard_task_runner.py:80} INFO - Job 100: Subtask cria_pasta_mes_ano
[2023-08-15 20:09:17,557] {task_command.py:370} INFO - Running <TaskInstance: dados_climaticos.cria_pasta_mes_ano scheduled__2023-01-23T00:00:00+00:00 [running]> on host ubuntu.internal.cloudapp.net
[2023-08-15 20:09:17,594] {taskinstance.py:1889} ERROR - Task failed with exception
Traceback (most recent call last):
  File "/home/guilherme/airflow/venv/lib/python3.9/site-packages/airflow/models/taskinstance.py", line 1451, in _run_raw_task
    self._execute_task_with_callbacks(context, test_mode)
  File "/home/guilherme/airflow/venv/lib/python3.9/site-packages/airflow/models/taskinstance.py", line 1555, in _execute_task_with_callbacks
    task_orig = self.render_templates(context=context)
  File "/home/guilherme/airflow/venv/lib/python3.9/site-packages/airflow/models/taskinstance.py", line 2212, in render_templates
    rendered_task = self.task.render_template_fields(context)
  File "/home/guilherme/airflow/venv/lib/python3.9/site-packages/airflow/models/baseoperator.py", line 1185, in render_template_fields
    self._do_render_template_fields(self, self.template_fields, context, jinja_env, set())
  File "/home/guilherme/airflow/venv/lib/python3.9/site-packages/airflow/utils/session.py", line 71, in wrapper
    return func(*args, session=session, **kwargs)
  File "/home/guilherme/airflow/venv/lib/python3.9/site-packages/airflow/models/abstractoperator.py", line 344, in _do_render_template_fields
    rendered_content = self.render_template(
  File "/home/guilherme/airflow/venv/lib/python3.9/site-packages/airflow/models/abstractoperator.py", line 387, in render_template
    template = jinja_env.from_string(value)
  File "/home/guilherme/airflow/venv/lib/python3.9/site-packages/jinja2/environment.py", line 1092, in from_string
    return cls.from_code(self, self.compile(source), gs, None)
  File "/home/guilherme/airflow/venv/lib/python3.9/site-packages/jinja2/environment.py", line 757, in compile
    self.handle_exception(source=source_hint)
  File "/home/guilherme/airflow/venv/lib/python3.9/site-packages/jinja2/environment.py", line 925, in handle_exception
    raise rewrite_traceback_stack(source=source)
  File "<unknown>", line 1, in template
jinja2.exceptions.TemplateSyntaxError: unexpected end of template, expected ','.
[2023-08-15 20:09:17,598] {taskinstance.py:1395} INFO - Marking task as FAILED. dag_id=dados_climaticos, task_id=cria_pasta_mes_ano, execution_date=20230123T000000, start_date=20230815T200917, end_date=20230815T200917
[2023-08-15 20:09:17,624] {standard_task_runner.py:92} ERROR - Failed to execute job 100 for task cria_pasta_mes_ano (unexpected end of template, expected ','.; 47144)
[2023-08-15 20:09:17,632] {local_task_job.py:156} INFO - Task exited with return code 1
[2023-08-15 20:09:17,667] {local_task_job.py:273} INFO - 0 downstream tasks scheduled from follow-on schedule check
[2023-08-15 20:27:44,371] {taskinstance.py:1159} INFO - Dependencies all met for <TaskInstance: dados_climaticos.cria_pasta_mes_ano scheduled__2023-01-23T00:00:00+00:00 [queued]>
[2023-08-15 20:27:44,376] {taskinstance.py:1159} INFO - Dependencies all met for <TaskInstance: dados_climaticos.cria_pasta_mes_ano scheduled__2023-01-23T00:00:00+00:00 [queued]>
[2023-08-15 20:27:44,376] {taskinstance.py:1356} INFO - 
--------------------------------------------------------------------------------
[2023-08-15 20:27:44,376] {taskinstance.py:1357} INFO - Starting attempt 1 of 1
[2023-08-15 20:27:44,376] {taskinstance.py:1358} INFO - 
--------------------------------------------------------------------------------
[2023-08-15 20:27:44,402] {taskinstance.py:1377} INFO - Executing <Task(BashOperator): cria_pasta_mes_ano> on 2023-01-23 00:00:00+00:00
[2023-08-15 20:27:44,405] {standard_task_runner.py:52} INFO - Started process 50849 to run task
[2023-08-15 20:27:44,410] {standard_task_runner.py:79} INFO - Running: ['airflow', 'tasks', 'run', 'dados_climaticos', 'cria_pasta_mes_ano', 'scheduled__2023-01-23T00:00:00+00:00', '--job-id', '141', '--raw', '--subdir', 'DAGS_FOLDER/dados_climatics.py', '--cfg-path', '/tmp/tmpu5rv3hmw', '--error-file', '/tmp/tmp6dx43_px']
[2023-08-15 20:27:44,411] {standard_task_runner.py:80} INFO - Job 141: Subtask cria_pasta_mes_ano
[2023-08-15 20:27:44,473] {task_command.py:370} INFO - Running <TaskInstance: dados_climaticos.cria_pasta_mes_ano scheduled__2023-01-23T00:00:00+00:00 [running]> on host ubuntu.internal.cloudapp.net
[2023-08-15 20:27:44,545] {taskinstance.py:1569} INFO - Exporting the following env vars:
AIRFLOW_CTX_DAG_OWNER=airflow
AIRFLOW_CTX_DAG_ID=dados_climaticos
AIRFLOW_CTX_TASK_ID=cria_pasta_mes_ano
AIRFLOW_CTX_EXECUTION_DATE=2023-01-23T00:00:00+00:00
AIRFLOW_CTX_TRY_NUMBER=1
AIRFLOW_CTX_DAG_RUN_ID=scheduled__2023-01-23T00:00:00+00:00
[2023-08-15 20:27:44,546] {subprocess.py:62} INFO - Tmp dir root location: 
 /tmp
[2023-08-15 20:27:44,546] {subprocess.py:74} INFO - Running command: ['bash', '-c', 'mkdir -p "/home/guilherme/airflow/semana=2023-01"']
[2023-08-15 20:27:44,554] {subprocess.py:85} INFO - Output:
[2023-08-15 20:27:44,556] {subprocess.py:96} INFO - Command exited with return code 0
[2023-08-15 20:27:44,592] {taskinstance.py:1395} INFO - Marking task as SUCCESS. dag_id=dados_climaticos, task_id=cria_pasta_mes_ano, execution_date=20230123T000000, start_date=20230815T202744, end_date=20230815T202744
[2023-08-15 20:27:44,622] {local_task_job.py:156} INFO - Task exited with return code 0
[2023-08-15 20:27:44,655] {local_task_job.py:273} INFO - 1 downstream tasks scheduled from follow-on schedule check
[2023-08-15 20:39:29,052] {taskinstance.py:1159} INFO - Dependencies all met for <TaskInstance: dados_climaticos.cria_pasta_mes_ano scheduled__2023-01-23T00:00:00+00:00 [queued]>
[2023-08-15 20:39:29,058] {taskinstance.py:1159} INFO - Dependencies all met for <TaskInstance: dados_climaticos.cria_pasta_mes_ano scheduled__2023-01-23T00:00:00+00:00 [queued]>
[2023-08-15 20:39:29,058] {taskinstance.py:1356} INFO - 
--------------------------------------------------------------------------------
[2023-08-15 20:39:29,058] {taskinstance.py:1357} INFO - Starting attempt 1 of 1
[2023-08-15 20:39:29,058] {taskinstance.py:1358} INFO - 
--------------------------------------------------------------------------------
[2023-08-15 20:39:29,081] {taskinstance.py:1377} INFO - Executing <Task(BashOperator): cria_pasta_mes_ano> on 2023-01-23 00:00:00+00:00
[2023-08-15 20:39:29,085] {standard_task_runner.py:52} INFO - Started process 55837 to run task
[2023-08-15 20:39:29,091] {standard_task_runner.py:79} INFO - Running: ['airflow', 'tasks', 'run', 'dados_climaticos', 'cria_pasta_mes_ano', 'scheduled__2023-01-23T00:00:00+00:00', '--job-id', '242', '--raw', '--subdir', 'DAGS_FOLDER/dados_climatics.py', '--cfg-path', '/tmp/tmp87ufh47j', '--error-file', '/tmp/tmpxhwqofaw']
[2023-08-15 20:39:29,092] {standard_task_runner.py:80} INFO - Job 242: Subtask cria_pasta_mes_ano
[2023-08-15 20:39:29,150] {task_command.py:370} INFO - Running <TaskInstance: dados_climaticos.cria_pasta_mes_ano scheduled__2023-01-23T00:00:00+00:00 [running]> on host ubuntu.internal.cloudapp.net
[2023-08-15 20:39:29,239] {taskinstance.py:1569} INFO - Exporting the following env vars:
AIRFLOW_CTX_DAG_OWNER=airflow
AIRFLOW_CTX_DAG_ID=dados_climaticos
AIRFLOW_CTX_TASK_ID=cria_pasta_mes_ano
AIRFLOW_CTX_EXECUTION_DATE=2023-01-23T00:00:00+00:00
AIRFLOW_CTX_TRY_NUMBER=1
AIRFLOW_CTX_DAG_RUN_ID=scheduled__2023-01-23T00:00:00+00:00
[2023-08-15 20:39:29,241] {subprocess.py:62} INFO - Tmp dir root location: 
 /tmp
[2023-08-15 20:39:29,241] {subprocess.py:74} INFO - Running command: ['bash', '-c', 'mkdir -p "/home/guilherme/airflow/dados/semana=2023-01"']
[2023-08-15 20:39:29,250] {subprocess.py:85} INFO - Output:
[2023-08-15 20:39:29,252] {subprocess.py:96} INFO - Command exited with return code 0
[2023-08-15 20:39:29,287] {taskinstance.py:1395} INFO - Marking task as SUCCESS. dag_id=dados_climaticos, task_id=cria_pasta_mes_ano, execution_date=20230123T000000, start_date=20230815T203929, end_date=20230815T203929
[2023-08-15 20:39:29,344] {local_task_job.py:156} INFO - Task exited with return code 0
[2023-08-15 20:39:29,383] {local_task_job.py:273} INFO - 1 downstream tasks scheduled from follow-on schedule check
