[2023-08-15 20:00:59,390] {taskinstance.py:1159} INFO - Dependencies all met for <TaskInstance: dados_climaticos.cria_pasta scheduled__2023-06-19T00:00:00+00:00 [queued]>
[2023-08-15 20:00:59,400] {taskinstance.py:1159} INFO - Dependencies all met for <TaskInstance: dados_climaticos.cria_pasta scheduled__2023-06-19T00:00:00+00:00 [queued]>
[2023-08-15 20:00:59,400] {taskinstance.py:1356} INFO - 
--------------------------------------------------------------------------------
[2023-08-15 20:00:59,400] {taskinstance.py:1357} INFO - Starting attempt 1 of 1
[2023-08-15 20:00:59,400] {taskinstance.py:1358} INFO - 
--------------------------------------------------------------------------------
[2023-08-15 20:00:59,449] {taskinstance.py:1377} INFO - Executing <Task(BashOperator): cria_pasta> on 2023-06-19 00:00:00+00:00
[2023-08-15 20:00:59,453] {standard_task_runner.py:52} INFO - Started process 42824 to run task
[2023-08-15 20:00:59,464] {standard_task_runner.py:79} INFO - Running: ['airflow', 'tasks', 'run', 'dados_climaticos', 'cria_pasta', 'scheduled__2023-06-19T00:00:00+00:00', '--job-id', '61', '--raw', '--subdir', 'DAGS_FOLDER/dados_climatics.py', '--cfg-path', '/tmp/tmpv30na_zg', '--error-file', '/tmp/tmpdf5y6tvq']
[2023-08-15 20:00:59,465] {standard_task_runner.py:80} INFO - Job 61: Subtask cria_pasta
[2023-08-15 20:00:59,583] {task_command.py:370} INFO - Running <TaskInstance: dados_climaticos.cria_pasta scheduled__2023-06-19T00:00:00+00:00 [running]> on host ubuntu.internal.cloudapp.net
[2023-08-15 20:00:59,667] {taskinstance.py:1889} ERROR - Task failed with exception
Traceback (most recent call last):
  File "/home/guilherme/airflow/venv/lib/python3.9/site-packages/airflow/models/taskinstance.py", line 1451, in _run_raw_task
    self._execute_task_with_callbacks(context, test_mode)
  File "/home/guilherme/airflow/venv/lib/python3.9/site-packages/airflow/models/taskinstance.py", line 1555, in _execute_task_with_callbacks
    task_orig = self.render_templates(context=context)
  File "/home/guilherme/airflow/venv/lib/python3.9/site-packages/airflow/models/taskinstance.py", line 2212, in render_templates
    rendered_task = self.task.render_template_fields(context)
  File "/home/guilherme/airflow/venv/lib/python3.9/site-packages/airflow/models/baseoperator.py", line 1185, in render_template_fields
    self._do_render_template_fields(self, self.template_fields, context, jinja_env, set())
  File "/home/guilherme/airflow/venv/lib/python3.9/site-packages/airflow/utils/session.py", line 71, in wrapper
    return func(*args, session=session, **kwargs)
  File "/home/guilherme/airflow/venv/lib/python3.9/site-packages/airflow/models/abstractoperator.py", line 344, in _do_render_template_fields
    rendered_content = self.render_template(
  File "/home/guilherme/airflow/venv/lib/python3.9/site-packages/airflow/models/abstractoperator.py", line 387, in render_template
    template = jinja_env.from_string(value)
  File "/home/guilherme/airflow/venv/lib/python3.9/site-packages/jinja2/environment.py", line 1092, in from_string
    return cls.from_code(self, self.compile(source), gs, None)
  File "/home/guilherme/airflow/venv/lib/python3.9/site-packages/jinja2/environment.py", line 757, in compile
    self.handle_exception(source=source_hint)
  File "/home/guilherme/airflow/venv/lib/python3.9/site-packages/jinja2/environment.py", line 925, in handle_exception
    raise rewrite_traceback_stack(source=source)
  File "<unknown>", line 1, in template
jinja2.exceptions.TemplateSyntaxError: unexpected end of template, expected ','.
[2023-08-15 20:00:59,686] {taskinstance.py:1395} INFO - Marking task as FAILED. dag_id=dados_climaticos, task_id=cria_pasta, execution_date=20230619T000000, start_date=20230815T200059, end_date=20230815T200059
[2023-08-15 20:00:59,749] {standard_task_runner.py:92} ERROR - Failed to execute job 61 for task cria_pasta (unexpected end of template, expected ','.; 42824)
[2023-08-15 20:00:59,769] {local_task_job.py:156} INFO - Task exited with return code 1
[2023-08-15 20:00:59,821] {local_task_job.py:273} INFO - 0 downstream tasks scheduled from follow-on schedule check
[2023-08-15 20:04:47,214] {taskinstance.py:1159} INFO - Dependencies all met for <TaskInstance: dados_climaticos.cria_pasta scheduled__2023-06-19T00:00:00+00:00 [queued]>
[2023-08-15 20:04:47,220] {taskinstance.py:1159} INFO - Dependencies all met for <TaskInstance: dados_climaticos.cria_pasta scheduled__2023-06-19T00:00:00+00:00 [queued]>
[2023-08-15 20:04:47,220] {taskinstance.py:1356} INFO - 
--------------------------------------------------------------------------------
[2023-08-15 20:04:47,220] {taskinstance.py:1357} INFO - Starting attempt 1 of 1
[2023-08-15 20:04:47,220] {taskinstance.py:1358} INFO - 
--------------------------------------------------------------------------------
[2023-08-15 20:04:47,246] {taskinstance.py:1377} INFO - Executing <Task(BashOperator): cria_pasta> on 2023-06-19 00:00:00+00:00
[2023-08-15 20:04:47,249] {standard_task_runner.py:52} INFO - Started process 45346 to run task
[2023-08-15 20:04:47,254] {standard_task_runner.py:79} INFO - Running: ['airflow', 'tasks', 'run', 'dados_climaticos', 'cria_pasta', 'scheduled__2023-06-19T00:00:00+00:00', '--job-id', '66', '--raw', '--subdir', 'DAGS_FOLDER/dados_climatics.py', '--cfg-path', '/tmp/tmpj4wnaeg9', '--error-file', '/tmp/tmpeqm4fyqm']
[2023-08-15 20:04:47,255] {standard_task_runner.py:80} INFO - Job 66: Subtask cria_pasta
[2023-08-15 20:04:47,308] {task_command.py:370} INFO - Running <TaskInstance: dados_climaticos.cria_pasta scheduled__2023-06-19T00:00:00+00:00 [running]> on host ubuntu.internal.cloudapp.net
[2023-08-15 20:04:47,343] {taskinstance.py:1889} ERROR - Task failed with exception
Traceback (most recent call last):
  File "/home/guilherme/airflow/venv/lib/python3.9/site-packages/airflow/models/taskinstance.py", line 1451, in _run_raw_task
    self._execute_task_with_callbacks(context, test_mode)
  File "/home/guilherme/airflow/venv/lib/python3.9/site-packages/airflow/models/taskinstance.py", line 1555, in _execute_task_with_callbacks
    task_orig = self.render_templates(context=context)
  File "/home/guilherme/airflow/venv/lib/python3.9/site-packages/airflow/models/taskinstance.py", line 2212, in render_templates
    rendered_task = self.task.render_template_fields(context)
  File "/home/guilherme/airflow/venv/lib/python3.9/site-packages/airflow/models/baseoperator.py", line 1185, in render_template_fields
    self._do_render_template_fields(self, self.template_fields, context, jinja_env, set())
  File "/home/guilherme/airflow/venv/lib/python3.9/site-packages/airflow/utils/session.py", line 71, in wrapper
    return func(*args, session=session, **kwargs)
  File "/home/guilherme/airflow/venv/lib/python3.9/site-packages/airflow/models/abstractoperator.py", line 344, in _do_render_template_fields
    rendered_content = self.render_template(
  File "/home/guilherme/airflow/venv/lib/python3.9/site-packages/airflow/models/abstractoperator.py", line 387, in render_template
    template = jinja_env.from_string(value)
  File "/home/guilherme/airflow/venv/lib/python3.9/site-packages/jinja2/environment.py", line 1092, in from_string
    return cls.from_code(self, self.compile(source), gs, None)
  File "/home/guilherme/airflow/venv/lib/python3.9/site-packages/jinja2/environment.py", line 757, in compile
    self.handle_exception(source=source_hint)
  File "/home/guilherme/airflow/venv/lib/python3.9/site-packages/jinja2/environment.py", line 925, in handle_exception
    raise rewrite_traceback_stack(source=source)
  File "<unknown>", line 1, in template
jinja2.exceptions.TemplateSyntaxError: unexpected end of template, expected ','.
[2023-08-15 20:04:47,347] {taskinstance.py:1395} INFO - Marking task as FAILED. dag_id=dados_climaticos, task_id=cria_pasta, execution_date=20230619T000000, start_date=20230815T200447, end_date=20230815T200447
[2023-08-15 20:04:47,372] {standard_task_runner.py:92} ERROR - Failed to execute job 66 for task cria_pasta (unexpected end of template, expected ','.; 45346)
[2023-08-15 20:04:47,386] {local_task_job.py:156} INFO - Task exited with return code 1
[2023-08-15 20:04:47,424] {local_task_job.py:273} INFO - 0 downstream tasks scheduled from follow-on schedule check
