[2023-08-15 19:59:45,209] {taskinstance.py:1159} INFO - Dependencies all met for <TaskInstance: dados_climaticos.cria_pasta scheduled__2022-11-14T00:00:00+00:00 [queued]>
[2023-08-15 19:59:45,213] {taskinstance.py:1159} INFO - Dependencies all met for <TaskInstance: dados_climaticos.cria_pasta scheduled__2022-11-14T00:00:00+00:00 [queued]>
[2023-08-15 19:59:45,213] {taskinstance.py:1356} INFO - 
--------------------------------------------------------------------------------
[2023-08-15 19:59:45,213] {taskinstance.py:1357} INFO - Starting attempt 1 of 1
[2023-08-15 19:59:45,213] {taskinstance.py:1358} INFO - 
--------------------------------------------------------------------------------
[2023-08-15 19:59:45,240] {taskinstance.py:1377} INFO - Executing <Task(BashOperator): cria_pasta> on 2022-11-14 00:00:00+00:00
[2023-08-15 19:59:45,243] {standard_task_runner.py:52} INFO - Started process 41911 to run task
[2023-08-15 19:59:45,248] {standard_task_runner.py:79} INFO - Running: ['airflow', 'tasks', 'run', 'dados_climaticos', 'cria_pasta', 'scheduled__2022-11-14T00:00:00+00:00', '--job-id', '30', '--raw', '--subdir', 'DAGS_FOLDER/dados_climatics.py', '--cfg-path', '/tmp/tmpxot7y1k4', '--error-file', '/tmp/tmpg8joc6xc']
[2023-08-15 19:59:45,248] {standard_task_runner.py:80} INFO - Job 30: Subtask cria_pasta
[2023-08-15 19:59:45,299] {task_command.py:370} INFO - Running <TaskInstance: dados_climaticos.cria_pasta scheduled__2022-11-14T00:00:00+00:00 [running]> on host ubuntu.internal.cloudapp.net
[2023-08-15 19:59:45,334] {taskinstance.py:1889} ERROR - Task failed with exception
Traceback (most recent call last):
  File "/home/guilherme/airflow/venv/lib/python3.9/site-packages/airflow/models/taskinstance.py", line 1451, in _run_raw_task
    self._execute_task_with_callbacks(context, test_mode)
  File "/home/guilherme/airflow/venv/lib/python3.9/site-packages/airflow/models/taskinstance.py", line 1555, in _execute_task_with_callbacks
    task_orig = self.render_templates(context=context)
  File "/home/guilherme/airflow/venv/lib/python3.9/site-packages/airflow/models/taskinstance.py", line 2212, in render_templates
    rendered_task = self.task.render_template_fields(context)
  File "/home/guilherme/airflow/venv/lib/python3.9/site-packages/airflow/models/baseoperator.py", line 1185, in render_template_fields
    self._do_render_template_fields(self, self.template_fields, context, jinja_env, set())
  File "/home/guilherme/airflow/venv/lib/python3.9/site-packages/airflow/utils/session.py", line 71, in wrapper
    return func(*args, session=session, **kwargs)
  File "/home/guilherme/airflow/venv/lib/python3.9/site-packages/airflow/models/abstractoperator.py", line 344, in _do_render_template_fields
    rendered_content = self.render_template(
  File "/home/guilherme/airflow/venv/lib/python3.9/site-packages/airflow/models/abstractoperator.py", line 387, in render_template
    template = jinja_env.from_string(value)
  File "/home/guilherme/airflow/venv/lib/python3.9/site-packages/jinja2/environment.py", line 1092, in from_string
    return cls.from_code(self, self.compile(source), gs, None)
  File "/home/guilherme/airflow/venv/lib/python3.9/site-packages/jinja2/environment.py", line 757, in compile
    self.handle_exception(source=source_hint)
  File "/home/guilherme/airflow/venv/lib/python3.9/site-packages/jinja2/environment.py", line 925, in handle_exception
    raise rewrite_traceback_stack(source=source)
  File "<unknown>", line 1, in template
jinja2.exceptions.TemplateSyntaxError: unexpected end of template, expected ','.
[2023-08-15 19:59:45,337] {taskinstance.py:1395} INFO - Marking task as FAILED. dag_id=dados_climaticos, task_id=cria_pasta, execution_date=20221114T000000, start_date=20230815T195945, end_date=20230815T195945
[2023-08-15 19:59:45,360] {standard_task_runner.py:92} ERROR - Failed to execute job 30 for task cria_pasta (unexpected end of template, expected ','.; 41911)
[2023-08-15 19:59:45,379] {local_task_job.py:156} INFO - Task exited with return code 1
[2023-08-15 19:59:45,419] {local_task_job.py:273} INFO - 0 downstream tasks scheduled from follow-on schedule check
[2023-08-15 20:02:26,389] {taskinstance.py:1159} INFO - Dependencies all met for <TaskInstance: dados_climaticos.cria_pasta scheduled__2022-11-14T00:00:00+00:00 [queued]>
[2023-08-15 20:02:26,395] {taskinstance.py:1159} INFO - Dependencies all met for <TaskInstance: dados_climaticos.cria_pasta scheduled__2022-11-14T00:00:00+00:00 [queued]>
[2023-08-15 20:02:26,395] {taskinstance.py:1356} INFO - 
--------------------------------------------------------------------------------
[2023-08-15 20:02:26,395] {taskinstance.py:1357} INFO - Starting attempt 1 of 1
[2023-08-15 20:02:26,395] {taskinstance.py:1358} INFO - 
--------------------------------------------------------------------------------
[2023-08-15 20:02:26,417] {taskinstance.py:1377} INFO - Executing <Task(BashOperator): cria_pasta> on 2022-11-14 00:00:00+00:00
[2023-08-15 20:02:26,421] {standard_task_runner.py:52} INFO - Started process 43820 to run task
[2023-08-15 20:02:26,426] {standard_task_runner.py:79} INFO - Running: ['airflow', 'tasks', 'run', 'dados_climaticos', 'cria_pasta', 'scheduled__2022-11-14T00:00:00+00:00', '--job-id', '32', '--raw', '--subdir', 'DAGS_FOLDER/dados_climatics.py', '--cfg-path', '/tmp/tmpe1rfw4n1', '--error-file', '/tmp/tmpwtad78c9']
[2023-08-15 20:02:26,426] {standard_task_runner.py:80} INFO - Job 32: Subtask cria_pasta
[2023-08-15 20:02:26,483] {task_command.py:370} INFO - Running <TaskInstance: dados_climaticos.cria_pasta scheduled__2022-11-14T00:00:00+00:00 [running]> on host ubuntu.internal.cloudapp.net
[2023-08-15 20:02:26,522] {taskinstance.py:1889} ERROR - Task failed with exception
Traceback (most recent call last):
  File "/home/guilherme/airflow/venv/lib/python3.9/site-packages/airflow/models/taskinstance.py", line 1451, in _run_raw_task
    self._execute_task_with_callbacks(context, test_mode)
  File "/home/guilherme/airflow/venv/lib/python3.9/site-packages/airflow/models/taskinstance.py", line 1555, in _execute_task_with_callbacks
    task_orig = self.render_templates(context=context)
  File "/home/guilherme/airflow/venv/lib/python3.9/site-packages/airflow/models/taskinstance.py", line 2212, in render_templates
    rendered_task = self.task.render_template_fields(context)
  File "/home/guilherme/airflow/venv/lib/python3.9/site-packages/airflow/models/baseoperator.py", line 1185, in render_template_fields
    self._do_render_template_fields(self, self.template_fields, context, jinja_env, set())
  File "/home/guilherme/airflow/venv/lib/python3.9/site-packages/airflow/utils/session.py", line 71, in wrapper
    return func(*args, session=session, **kwargs)
  File "/home/guilherme/airflow/venv/lib/python3.9/site-packages/airflow/models/abstractoperator.py", line 344, in _do_render_template_fields
    rendered_content = self.render_template(
  File "/home/guilherme/airflow/venv/lib/python3.9/site-packages/airflow/models/abstractoperator.py", line 387, in render_template
    template = jinja_env.from_string(value)
  File "/home/guilherme/airflow/venv/lib/python3.9/site-packages/jinja2/environment.py", line 1092, in from_string
    return cls.from_code(self, self.compile(source), gs, None)
  File "/home/guilherme/airflow/venv/lib/python3.9/site-packages/jinja2/environment.py", line 757, in compile
    self.handle_exception(source=source_hint)
  File "/home/guilherme/airflow/venv/lib/python3.9/site-packages/jinja2/environment.py", line 925, in handle_exception
    raise rewrite_traceback_stack(source=source)
  File "<unknown>", line 1, in template
jinja2.exceptions.TemplateSyntaxError: unexpected end of template, expected ','.
[2023-08-15 20:02:26,526] {taskinstance.py:1395} INFO - Marking task as FAILED. dag_id=dados_climaticos, task_id=cria_pasta, execution_date=20221114T000000, start_date=20230815T200226, end_date=20230815T200226
[2023-08-15 20:02:26,546] {standard_task_runner.py:92} ERROR - Failed to execute job 32 for task cria_pasta (unexpected end of template, expected ','.; 43820)
[2023-08-15 20:02:26,557] {local_task_job.py:156} INFO - Task exited with return code 1
[2023-08-15 20:02:26,599] {local_task_job.py:273} INFO - 0 downstream tasks scheduled from follow-on schedule check
