[2023-08-15 20:09:19,468] {taskinstance.py:1159} INFO - Dependencies all met for <TaskInstance: dados_climaticos.cria_pasta_mes_ano scheduled__2023-01-30T00:00:00+00:00 [queued]>
[2023-08-15 20:09:19,474] {taskinstance.py:1159} INFO - Dependencies all met for <TaskInstance: dados_climaticos.cria_pasta_mes_ano scheduled__2023-01-30T00:00:00+00:00 [queued]>
[2023-08-15 20:09:19,474] {taskinstance.py:1356} INFO - 
--------------------------------------------------------------------------------
[2023-08-15 20:09:19,474] {taskinstance.py:1357} INFO - Starting attempt 1 of 1
[2023-08-15 20:09:19,474] {taskinstance.py:1358} INFO - 
--------------------------------------------------------------------------------
[2023-08-15 20:09:19,497] {taskinstance.py:1377} INFO - Executing <Task(BashOperator): cria_pasta_mes_ano> on 2023-01-30 00:00:00+00:00
[2023-08-15 20:09:19,501] {standard_task_runner.py:52} INFO - Started process 47148 to run task
[2023-08-15 20:09:19,506] {standard_task_runner.py:79} INFO - Running: ['airflow', 'tasks', 'run', 'dados_climaticos', 'cria_pasta_mes_ano', 'scheduled__2023-01-30T00:00:00+00:00', '--job-id', '101', '--raw', '--subdir', 'DAGS_FOLDER/dados_climatics.py', '--cfg-path', '/tmp/tmpuvcyvyvc', '--error-file', '/tmp/tmpd4ehl8nu']
[2023-08-15 20:09:19,506] {standard_task_runner.py:80} INFO - Job 101: Subtask cria_pasta_mes_ano
[2023-08-15 20:09:19,564] {task_command.py:370} INFO - Running <TaskInstance: dados_climaticos.cria_pasta_mes_ano scheduled__2023-01-30T00:00:00+00:00 [running]> on host ubuntu.internal.cloudapp.net
[2023-08-15 20:09:19,601] {taskinstance.py:1889} ERROR - Task failed with exception
Traceback (most recent call last):
  File "/home/guilherme/airflow/venv/lib/python3.9/site-packages/airflow/models/taskinstance.py", line 1451, in _run_raw_task
    self._execute_task_with_callbacks(context, test_mode)
  File "/home/guilherme/airflow/venv/lib/python3.9/site-packages/airflow/models/taskinstance.py", line 1555, in _execute_task_with_callbacks
    task_orig = self.render_templates(context=context)
  File "/home/guilherme/airflow/venv/lib/python3.9/site-packages/airflow/models/taskinstance.py", line 2212, in render_templates
    rendered_task = self.task.render_template_fields(context)
  File "/home/guilherme/airflow/venv/lib/python3.9/site-packages/airflow/models/baseoperator.py", line 1185, in render_template_fields
    self._do_render_template_fields(self, self.template_fields, context, jinja_env, set())
  File "/home/guilherme/airflow/venv/lib/python3.9/site-packages/airflow/utils/session.py", line 71, in wrapper
    return func(*args, session=session, **kwargs)
  File "/home/guilherme/airflow/venv/lib/python3.9/site-packages/airflow/models/abstractoperator.py", line 344, in _do_render_template_fields
    rendered_content = self.render_template(
  File "/home/guilherme/airflow/venv/lib/python3.9/site-packages/airflow/models/abstractoperator.py", line 387, in render_template
    template = jinja_env.from_string(value)
  File "/home/guilherme/airflow/venv/lib/python3.9/site-packages/jinja2/environment.py", line 1092, in from_string
    return cls.from_code(self, self.compile(source), gs, None)
  File "/home/guilherme/airflow/venv/lib/python3.9/site-packages/jinja2/environment.py", line 757, in compile
    self.handle_exception(source=source_hint)
  File "/home/guilherme/airflow/venv/lib/python3.9/site-packages/jinja2/environment.py", line 925, in handle_exception
    raise rewrite_traceback_stack(source=source)
  File "<unknown>", line 1, in template
jinja2.exceptions.TemplateSyntaxError: unexpected end of template, expected ','.
[2023-08-15 20:09:19,606] {taskinstance.py:1395} INFO - Marking task as FAILED. dag_id=dados_climaticos, task_id=cria_pasta_mes_ano, execution_date=20230130T000000, start_date=20230815T200919, end_date=20230815T200919
[2023-08-15 20:09:19,630] {standard_task_runner.py:92} ERROR - Failed to execute job 101 for task cria_pasta_mes_ano (unexpected end of template, expected ','.; 47148)
[2023-08-15 20:09:19,637] {local_task_job.py:156} INFO - Task exited with return code 1
[2023-08-15 20:09:19,674] {local_task_job.py:273} INFO - 0 downstream tasks scheduled from follow-on schedule check
[2023-08-15 20:27:48,183] {taskinstance.py:1159} INFO - Dependencies all met for <TaskInstance: dados_climaticos.cria_pasta_mes_ano scheduled__2023-01-30T00:00:00+00:00 [queued]>
[2023-08-15 20:27:48,189] {taskinstance.py:1159} INFO - Dependencies all met for <TaskInstance: dados_climaticos.cria_pasta_mes_ano scheduled__2023-01-30T00:00:00+00:00 [queued]>
[2023-08-15 20:27:48,189] {taskinstance.py:1356} INFO - 
--------------------------------------------------------------------------------
[2023-08-15 20:27:48,189] {taskinstance.py:1357} INFO - Starting attempt 1 of 1
[2023-08-15 20:27:48,189] {taskinstance.py:1358} INFO - 
--------------------------------------------------------------------------------
[2023-08-15 20:27:48,211] {taskinstance.py:1377} INFO - Executing <Task(BashOperator): cria_pasta_mes_ano> on 2023-01-30 00:00:00+00:00
[2023-08-15 20:27:48,214] {standard_task_runner.py:52} INFO - Started process 50913 to run task
[2023-08-15 20:27:48,219] {standard_task_runner.py:79} INFO - Running: ['airflow', 'tasks', 'run', 'dados_climaticos', 'cria_pasta_mes_ano', 'scheduled__2023-01-30T00:00:00+00:00', '--job-id', '143', '--raw', '--subdir', 'DAGS_FOLDER/dados_climatics.py', '--cfg-path', '/tmp/tmpbej_259j', '--error-file', '/tmp/tmpzfc6ceu6']
[2023-08-15 20:27:48,220] {standard_task_runner.py:80} INFO - Job 143: Subtask cria_pasta_mes_ano
[2023-08-15 20:27:48,273] {task_command.py:370} INFO - Running <TaskInstance: dados_climaticos.cria_pasta_mes_ano scheduled__2023-01-30T00:00:00+00:00 [running]> on host ubuntu.internal.cloudapp.net
[2023-08-15 20:27:48,344] {taskinstance.py:1569} INFO - Exporting the following env vars:
AIRFLOW_CTX_DAG_OWNER=airflow
AIRFLOW_CTX_DAG_ID=dados_climaticos
AIRFLOW_CTX_TASK_ID=cria_pasta_mes_ano
AIRFLOW_CTX_EXECUTION_DATE=2023-01-30T00:00:00+00:00
AIRFLOW_CTX_TRY_NUMBER=1
AIRFLOW_CTX_DAG_RUN_ID=scheduled__2023-01-30T00:00:00+00:00
[2023-08-15 20:27:48,344] {subprocess.py:62} INFO - Tmp dir root location: 
 /tmp
[2023-08-15 20:27:48,345] {subprocess.py:74} INFO - Running command: ['bash', '-c', 'mkdir -p "/home/guilherme/airflow/semana=2023-02"']
[2023-08-15 20:27:48,352] {subprocess.py:85} INFO - Output:
[2023-08-15 20:27:48,354] {subprocess.py:96} INFO - Command exited with return code 0
[2023-08-15 20:27:48,385] {taskinstance.py:1395} INFO - Marking task as SUCCESS. dag_id=dados_climaticos, task_id=cria_pasta_mes_ano, execution_date=20230130T000000, start_date=20230815T202748, end_date=20230815T202748
[2023-08-15 20:27:48,431] {local_task_job.py:156} INFO - Task exited with return code 0
[2023-08-15 20:27:48,467] {local_task_job.py:273} INFO - 1 downstream tasks scheduled from follow-on schedule check
[2023-08-15 20:39:33,773] {taskinstance.py:1159} INFO - Dependencies all met for <TaskInstance: dados_climaticos.cria_pasta_mes_ano scheduled__2023-01-30T00:00:00+00:00 [queued]>
[2023-08-15 20:39:33,779] {taskinstance.py:1159} INFO - Dependencies all met for <TaskInstance: dados_climaticos.cria_pasta_mes_ano scheduled__2023-01-30T00:00:00+00:00 [queued]>
[2023-08-15 20:39:33,779] {taskinstance.py:1356} INFO - 
--------------------------------------------------------------------------------
[2023-08-15 20:39:33,779] {taskinstance.py:1357} INFO - Starting attempt 1 of 1
[2023-08-15 20:39:33,779] {taskinstance.py:1358} INFO - 
--------------------------------------------------------------------------------
[2023-08-15 20:39:33,805] {taskinstance.py:1377} INFO - Executing <Task(BashOperator): cria_pasta_mes_ano> on 2023-01-30 00:00:00+00:00
[2023-08-15 20:39:33,809] {standard_task_runner.py:52} INFO - Started process 55899 to run task
[2023-08-15 20:39:33,814] {standard_task_runner.py:79} INFO - Running: ['airflow', 'tasks', 'run', 'dados_climaticos', 'cria_pasta_mes_ano', 'scheduled__2023-01-30T00:00:00+00:00', '--job-id', '244', '--raw', '--subdir', 'DAGS_FOLDER/dados_climatics.py', '--cfg-path', '/tmp/tmpjawmpyve', '--error-file', '/tmp/tmp4if2cwl8']
[2023-08-15 20:39:33,815] {standard_task_runner.py:80} INFO - Job 244: Subtask cria_pasta_mes_ano
[2023-08-15 20:39:33,876] {task_command.py:370} INFO - Running <TaskInstance: dados_climaticos.cria_pasta_mes_ano scheduled__2023-01-30T00:00:00+00:00 [running]> on host ubuntu.internal.cloudapp.net
[2023-08-15 20:39:33,949] {taskinstance.py:1569} INFO - Exporting the following env vars:
AIRFLOW_CTX_DAG_OWNER=airflow
AIRFLOW_CTX_DAG_ID=dados_climaticos
AIRFLOW_CTX_TASK_ID=cria_pasta_mes_ano
AIRFLOW_CTX_EXECUTION_DATE=2023-01-30T00:00:00+00:00
AIRFLOW_CTX_TRY_NUMBER=1
AIRFLOW_CTX_DAG_RUN_ID=scheduled__2023-01-30T00:00:00+00:00
[2023-08-15 20:39:33,951] {subprocess.py:62} INFO - Tmp dir root location: 
 /tmp
[2023-08-15 20:39:33,951] {subprocess.py:74} INFO - Running command: ['bash', '-c', 'mkdir -p "/home/guilherme/airflow/dados/semana=2023-02"']
[2023-08-15 20:39:33,959] {subprocess.py:85} INFO - Output:
[2023-08-15 20:39:33,962] {subprocess.py:96} INFO - Command exited with return code 0
[2023-08-15 20:39:34,000] {taskinstance.py:1395} INFO - Marking task as SUCCESS. dag_id=dados_climaticos, task_id=cria_pasta_mes_ano, execution_date=20230130T000000, start_date=20230815T203933, end_date=20230815T203934
[2023-08-15 20:39:34,026] {local_task_job.py:156} INFO - Task exited with return code 0
[2023-08-15 20:39:34,061] {local_task_job.py:273} INFO - 1 downstream tasks scheduled from follow-on schedule check
