[2023-08-15 20:09:29,899] {taskinstance.py:1159} INFO - Dependencies all met for <TaskInstance: dados_climaticos.cria_pasta_mes_ano scheduled__2023-02-27T00:00:00+00:00 [queued]>
[2023-08-15 20:09:29,904] {taskinstance.py:1159} INFO - Dependencies all met for <TaskInstance: dados_climaticos.cria_pasta_mes_ano scheduled__2023-02-27T00:00:00+00:00 [queued]>
[2023-08-15 20:09:29,904] {taskinstance.py:1356} INFO - 
--------------------------------------------------------------------------------
[2023-08-15 20:09:29,904] {taskinstance.py:1357} INFO - Starting attempt 1 of 1
[2023-08-15 20:09:29,904] {taskinstance.py:1358} INFO - 
--------------------------------------------------------------------------------
[2023-08-15 20:09:29,927] {taskinstance.py:1377} INFO - Executing <Task(BashOperator): cria_pasta_mes_ano> on 2023-02-27 00:00:00+00:00
[2023-08-15 20:09:29,931] {standard_task_runner.py:52} INFO - Started process 47268 to run task
[2023-08-15 20:09:29,935] {standard_task_runner.py:79} INFO - Running: ['airflow', 'tasks', 'run', 'dados_climaticos', 'cria_pasta_mes_ano', 'scheduled__2023-02-27T00:00:00+00:00', '--job-id', '105', '--raw', '--subdir', 'DAGS_FOLDER/dados_climatics.py', '--cfg-path', '/tmp/tmpukwi0uij', '--error-file', '/tmp/tmpl444z19x']
[2023-08-15 20:09:29,936] {standard_task_runner.py:80} INFO - Job 105: Subtask cria_pasta_mes_ano
[2023-08-15 20:09:29,991] {task_command.py:370} INFO - Running <TaskInstance: dados_climaticos.cria_pasta_mes_ano scheduled__2023-02-27T00:00:00+00:00 [running]> on host ubuntu.internal.cloudapp.net
[2023-08-15 20:09:30,027] {taskinstance.py:1889} ERROR - Task failed with exception
Traceback (most recent call last):
  File "/home/guilherme/airflow/venv/lib/python3.9/site-packages/airflow/models/taskinstance.py", line 1451, in _run_raw_task
    self._execute_task_with_callbacks(context, test_mode)
  File "/home/guilherme/airflow/venv/lib/python3.9/site-packages/airflow/models/taskinstance.py", line 1555, in _execute_task_with_callbacks
    task_orig = self.render_templates(context=context)
  File "/home/guilherme/airflow/venv/lib/python3.9/site-packages/airflow/models/taskinstance.py", line 2212, in render_templates
    rendered_task = self.task.render_template_fields(context)
  File "/home/guilherme/airflow/venv/lib/python3.9/site-packages/airflow/models/baseoperator.py", line 1185, in render_template_fields
    self._do_render_template_fields(self, self.template_fields, context, jinja_env, set())
  File "/home/guilherme/airflow/venv/lib/python3.9/site-packages/airflow/utils/session.py", line 71, in wrapper
    return func(*args, session=session, **kwargs)
  File "/home/guilherme/airflow/venv/lib/python3.9/site-packages/airflow/models/abstractoperator.py", line 344, in _do_render_template_fields
    rendered_content = self.render_template(
  File "/home/guilherme/airflow/venv/lib/python3.9/site-packages/airflow/models/abstractoperator.py", line 387, in render_template
    template = jinja_env.from_string(value)
  File "/home/guilherme/airflow/venv/lib/python3.9/site-packages/jinja2/environment.py", line 1092, in from_string
    return cls.from_code(self, self.compile(source), gs, None)
  File "/home/guilherme/airflow/venv/lib/python3.9/site-packages/jinja2/environment.py", line 757, in compile
    self.handle_exception(source=source_hint)
  File "/home/guilherme/airflow/venv/lib/python3.9/site-packages/jinja2/environment.py", line 925, in handle_exception
    raise rewrite_traceback_stack(source=source)
  File "<unknown>", line 1, in template
jinja2.exceptions.TemplateSyntaxError: unexpected end of template, expected ','.
[2023-08-15 20:09:30,030] {taskinstance.py:1395} INFO - Marking task as FAILED. dag_id=dados_climaticos, task_id=cria_pasta_mes_ano, execution_date=20230227T000000, start_date=20230815T200929, end_date=20230815T200930
[2023-08-15 20:09:30,060] {standard_task_runner.py:92} ERROR - Failed to execute job 105 for task cria_pasta_mes_ano (unexpected end of template, expected ','.; 47268)
[2023-08-15 20:09:30,067] {local_task_job.py:156} INFO - Task exited with return code 1
[2023-08-15 20:09:30,105] {local_task_job.py:273} INFO - 0 downstream tasks scheduled from follow-on schedule check
[2023-08-15 20:28:12,737] {taskinstance.py:1159} INFO - Dependencies all met for <TaskInstance: dados_climaticos.cria_pasta_mes_ano scheduled__2023-02-27T00:00:00+00:00 [queued]>
[2023-08-15 20:28:12,741] {taskinstance.py:1159} INFO - Dependencies all met for <TaskInstance: dados_climaticos.cria_pasta_mes_ano scheduled__2023-02-27T00:00:00+00:00 [queued]>
[2023-08-15 20:28:12,741] {taskinstance.py:1356} INFO - 
--------------------------------------------------------------------------------
[2023-08-15 20:28:12,742] {taskinstance.py:1357} INFO - Starting attempt 1 of 1
[2023-08-15 20:28:12,742] {taskinstance.py:1358} INFO - 
--------------------------------------------------------------------------------
[2023-08-15 20:28:12,764] {taskinstance.py:1377} INFO - Executing <Task(BashOperator): cria_pasta_mes_ano> on 2023-02-27 00:00:00+00:00
[2023-08-15 20:28:12,767] {standard_task_runner.py:52} INFO - Started process 51224 to run task
[2023-08-15 20:28:12,771] {standard_task_runner.py:79} INFO - Running: ['airflow', 'tasks', 'run', 'dados_climaticos', 'cria_pasta_mes_ano', 'scheduled__2023-02-27T00:00:00+00:00', '--job-id', '155', '--raw', '--subdir', 'DAGS_FOLDER/dados_climatics.py', '--cfg-path', '/tmp/tmpb_b9ftju', '--error-file', '/tmp/tmpesgjr37e']
[2023-08-15 20:28:12,772] {standard_task_runner.py:80} INFO - Job 155: Subtask cria_pasta_mes_ano
[2023-08-15 20:28:12,820] {task_command.py:370} INFO - Running <TaskInstance: dados_climaticos.cria_pasta_mes_ano scheduled__2023-02-27T00:00:00+00:00 [running]> on host ubuntu.internal.cloudapp.net
[2023-08-15 20:28:12,888] {taskinstance.py:1569} INFO - Exporting the following env vars:
AIRFLOW_CTX_DAG_OWNER=airflow
AIRFLOW_CTX_DAG_ID=dados_climaticos
AIRFLOW_CTX_TASK_ID=cria_pasta_mes_ano
AIRFLOW_CTX_EXECUTION_DATE=2023-02-27T00:00:00+00:00
AIRFLOW_CTX_TRY_NUMBER=1
AIRFLOW_CTX_DAG_RUN_ID=scheduled__2023-02-27T00:00:00+00:00
[2023-08-15 20:28:12,889] {subprocess.py:62} INFO - Tmp dir root location: 
 /tmp
[2023-08-15 20:28:12,889] {subprocess.py:74} INFO - Running command: ['bash', '-c', 'mkdir -p "/home/guilherme/airflow/semana=2023-03"']
[2023-08-15 20:28:12,896] {subprocess.py:85} INFO - Output:
[2023-08-15 20:28:12,898] {subprocess.py:96} INFO - Command exited with return code 0
[2023-08-15 20:28:12,929] {taskinstance.py:1395} INFO - Marking task as SUCCESS. dag_id=dados_climaticos, task_id=cria_pasta_mes_ano, execution_date=20230227T000000, start_date=20230815T202812, end_date=20230815T202812
[2023-08-15 20:28:12,983] {local_task_job.py:156} INFO - Task exited with return code 0
[2023-08-15 20:28:13,023] {local_task_job.py:273} INFO - 1 downstream tasks scheduled from follow-on schedule check
[2023-08-15 20:40:01,460] {taskinstance.py:1159} INFO - Dependencies all met for <TaskInstance: dados_climaticos.cria_pasta_mes_ano scheduled__2023-02-27T00:00:00+00:00 [queued]>
[2023-08-15 20:40:01,466] {taskinstance.py:1159} INFO - Dependencies all met for <TaskInstance: dados_climaticos.cria_pasta_mes_ano scheduled__2023-02-27T00:00:00+00:00 [queued]>
[2023-08-15 20:40:01,466] {taskinstance.py:1356} INFO - 
--------------------------------------------------------------------------------
[2023-08-15 20:40:01,466] {taskinstance.py:1357} INFO - Starting attempt 1 of 1
[2023-08-15 20:40:01,466] {taskinstance.py:1358} INFO - 
--------------------------------------------------------------------------------
[2023-08-15 20:40:01,496] {taskinstance.py:1377} INFO - Executing <Task(BashOperator): cria_pasta_mes_ano> on 2023-02-27 00:00:00+00:00
[2023-08-15 20:40:01,499] {standard_task_runner.py:52} INFO - Started process 56270 to run task
[2023-08-15 20:40:01,506] {standard_task_runner.py:79} INFO - Running: ['airflow', 'tasks', 'run', 'dados_climaticos', 'cria_pasta_mes_ano', 'scheduled__2023-02-27T00:00:00+00:00', '--job-id', '256', '--raw', '--subdir', 'DAGS_FOLDER/dados_climatics.py', '--cfg-path', '/tmp/tmpg9aeqzlw', '--error-file', '/tmp/tmpnhs5plst']
[2023-08-15 20:40:01,507] {standard_task_runner.py:80} INFO - Job 256: Subtask cria_pasta_mes_ano
[2023-08-15 20:40:01,573] {task_command.py:370} INFO - Running <TaskInstance: dados_climaticos.cria_pasta_mes_ano scheduled__2023-02-27T00:00:00+00:00 [running]> on host ubuntu.internal.cloudapp.net
[2023-08-15 20:40:01,654] {taskinstance.py:1569} INFO - Exporting the following env vars:
AIRFLOW_CTX_DAG_OWNER=airflow
AIRFLOW_CTX_DAG_ID=dados_climaticos
AIRFLOW_CTX_TASK_ID=cria_pasta_mes_ano
AIRFLOW_CTX_EXECUTION_DATE=2023-02-27T00:00:00+00:00
AIRFLOW_CTX_TRY_NUMBER=1
AIRFLOW_CTX_DAG_RUN_ID=scheduled__2023-02-27T00:00:00+00:00
[2023-08-15 20:40:01,655] {subprocess.py:62} INFO - Tmp dir root location: 
 /tmp
[2023-08-15 20:40:01,656] {subprocess.py:74} INFO - Running command: ['bash', '-c', 'mkdir -p "/home/guilherme/airflow/dados/semana=2023-03"']
[2023-08-15 20:40:01,664] {subprocess.py:85} INFO - Output:
[2023-08-15 20:40:01,666] {subprocess.py:96} INFO - Command exited with return code 0
[2023-08-15 20:40:01,708] {taskinstance.py:1395} INFO - Marking task as SUCCESS. dag_id=dados_climaticos, task_id=cria_pasta_mes_ano, execution_date=20230227T000000, start_date=20230815T204001, end_date=20230815T204001
[2023-08-15 20:40:01,758] {local_task_job.py:156} INFO - Task exited with return code 0
[2023-08-15 20:40:01,802] {local_task_job.py:273} INFO - 1 downstream tasks scheduled from follow-on schedule check
