[2023-08-15 20:00:49,091] {taskinstance.py:1159} INFO - Dependencies all met for <TaskInstance: dados_climaticos.cria_pasta scheduled__2023-05-22T00:00:00+00:00 [queued]>
[2023-08-15 20:00:49,096] {taskinstance.py:1159} INFO - Dependencies all met for <TaskInstance: dados_climaticos.cria_pasta scheduled__2023-05-22T00:00:00+00:00 [queued]>
[2023-08-15 20:00:49,096] {taskinstance.py:1356} INFO - 
--------------------------------------------------------------------------------
[2023-08-15 20:00:49,096] {taskinstance.py:1357} INFO - Starting attempt 1 of 1
[2023-08-15 20:00:49,096] {taskinstance.py:1358} INFO - 
--------------------------------------------------------------------------------
[2023-08-15 20:00:49,121] {taskinstance.py:1377} INFO - Executing <Task(BashOperator): cria_pasta> on 2023-05-22 00:00:00+00:00
[2023-08-15 20:00:49,124] {standard_task_runner.py:52} INFO - Started process 42704 to run task
[2023-08-15 20:00:49,128] {standard_task_runner.py:79} INFO - Running: ['airflow', 'tasks', 'run', 'dados_climaticos', 'cria_pasta', 'scheduled__2023-05-22T00:00:00+00:00', '--job-id', '57', '--raw', '--subdir', 'DAGS_FOLDER/dados_climatics.py', '--cfg-path', '/tmp/tmpyra2ovhz', '--error-file', '/tmp/tmpu56ae85e']
[2023-08-15 20:00:49,129] {standard_task_runner.py:80} INFO - Job 57: Subtask cria_pasta
[2023-08-15 20:00:49,178] {task_command.py:370} INFO - Running <TaskInstance: dados_climaticos.cria_pasta scheduled__2023-05-22T00:00:00+00:00 [running]> on host ubuntu.internal.cloudapp.net
[2023-08-15 20:00:49,217] {taskinstance.py:1889} ERROR - Task failed with exception
Traceback (most recent call last):
  File "/home/guilherme/airflow/venv/lib/python3.9/site-packages/airflow/models/taskinstance.py", line 1451, in _run_raw_task
    self._execute_task_with_callbacks(context, test_mode)
  File "/home/guilherme/airflow/venv/lib/python3.9/site-packages/airflow/models/taskinstance.py", line 1555, in _execute_task_with_callbacks
    task_orig = self.render_templates(context=context)
  File "/home/guilherme/airflow/venv/lib/python3.9/site-packages/airflow/models/taskinstance.py", line 2212, in render_templates
    rendered_task = self.task.render_template_fields(context)
  File "/home/guilherme/airflow/venv/lib/python3.9/site-packages/airflow/models/baseoperator.py", line 1185, in render_template_fields
    self._do_render_template_fields(self, self.template_fields, context, jinja_env, set())
  File "/home/guilherme/airflow/venv/lib/python3.9/site-packages/airflow/utils/session.py", line 71, in wrapper
    return func(*args, session=session, **kwargs)
  File "/home/guilherme/airflow/venv/lib/python3.9/site-packages/airflow/models/abstractoperator.py", line 344, in _do_render_template_fields
    rendered_content = self.render_template(
  File "/home/guilherme/airflow/venv/lib/python3.9/site-packages/airflow/models/abstractoperator.py", line 387, in render_template
    template = jinja_env.from_string(value)
  File "/home/guilherme/airflow/venv/lib/python3.9/site-packages/jinja2/environment.py", line 1092, in from_string
    return cls.from_code(self, self.compile(source), gs, None)
  File "/home/guilherme/airflow/venv/lib/python3.9/site-packages/jinja2/environment.py", line 757, in compile
    self.handle_exception(source=source_hint)
  File "/home/guilherme/airflow/venv/lib/python3.9/site-packages/jinja2/environment.py", line 925, in handle_exception
    raise rewrite_traceback_stack(source=source)
  File "<unknown>", line 1, in template
jinja2.exceptions.TemplateSyntaxError: unexpected end of template, expected ','.
[2023-08-15 20:00:49,220] {taskinstance.py:1395} INFO - Marking task as FAILED. dag_id=dados_climaticos, task_id=cria_pasta, execution_date=20230522T000000, start_date=20230815T200049, end_date=20230815T200049
[2023-08-15 20:00:49,245] {standard_task_runner.py:92} ERROR - Failed to execute job 57 for task cria_pasta (unexpected end of template, expected ','.; 42704)
[2023-08-15 20:00:49,260] {local_task_job.py:156} INFO - Task exited with return code 1
[2023-08-15 20:00:49,296] {local_task_job.py:273} INFO - 0 downstream tasks scheduled from follow-on schedule check
[2023-08-15 20:04:35,990] {taskinstance.py:1159} INFO - Dependencies all met for <TaskInstance: dados_climaticos.cria_pasta scheduled__2023-05-22T00:00:00+00:00 [queued]>
[2023-08-15 20:04:35,998] {taskinstance.py:1159} INFO - Dependencies all met for <TaskInstance: dados_climaticos.cria_pasta scheduled__2023-05-22T00:00:00+00:00 [queued]>
[2023-08-15 20:04:35,998] {taskinstance.py:1356} INFO - 
--------------------------------------------------------------------------------
[2023-08-15 20:04:35,998] {taskinstance.py:1357} INFO - Starting attempt 1 of 1
[2023-08-15 20:04:35,998] {taskinstance.py:1358} INFO - 
--------------------------------------------------------------------------------
[2023-08-15 20:04:36,029] {taskinstance.py:1377} INFO - Executing <Task(BashOperator): cria_pasta> on 2023-05-22 00:00:00+00:00
[2023-08-15 20:04:36,034] {standard_task_runner.py:52} INFO - Started process 45192 to run task
[2023-08-15 20:04:36,039] {standard_task_runner.py:79} INFO - Running: ['airflow', 'tasks', 'run', 'dados_climaticos', 'cria_pasta', 'scheduled__2023-05-22T00:00:00+00:00', '--job-id', '62', '--raw', '--subdir', 'DAGS_FOLDER/dados_climatics.py', '--cfg-path', '/tmp/tmptw03f__r', '--error-file', '/tmp/tmp395nhq6x']
[2023-08-15 20:04:36,040] {standard_task_runner.py:80} INFO - Job 62: Subtask cria_pasta
[2023-08-15 20:04:36,095] {task_command.py:370} INFO - Running <TaskInstance: dados_climaticos.cria_pasta scheduled__2023-05-22T00:00:00+00:00 [running]> on host ubuntu.internal.cloudapp.net
[2023-08-15 20:04:36,135] {taskinstance.py:1889} ERROR - Task failed with exception
Traceback (most recent call last):
  File "/home/guilherme/airflow/venv/lib/python3.9/site-packages/airflow/models/taskinstance.py", line 1451, in _run_raw_task
    self._execute_task_with_callbacks(context, test_mode)
  File "/home/guilherme/airflow/venv/lib/python3.9/site-packages/airflow/models/taskinstance.py", line 1555, in _execute_task_with_callbacks
    task_orig = self.render_templates(context=context)
  File "/home/guilherme/airflow/venv/lib/python3.9/site-packages/airflow/models/taskinstance.py", line 2212, in render_templates
    rendered_task = self.task.render_template_fields(context)
  File "/home/guilherme/airflow/venv/lib/python3.9/site-packages/airflow/models/baseoperator.py", line 1185, in render_template_fields
    self._do_render_template_fields(self, self.template_fields, context, jinja_env, set())
  File "/home/guilherme/airflow/venv/lib/python3.9/site-packages/airflow/utils/session.py", line 71, in wrapper
    return func(*args, session=session, **kwargs)
  File "/home/guilherme/airflow/venv/lib/python3.9/site-packages/airflow/models/abstractoperator.py", line 344, in _do_render_template_fields
    rendered_content = self.render_template(
  File "/home/guilherme/airflow/venv/lib/python3.9/site-packages/airflow/models/abstractoperator.py", line 387, in render_template
    template = jinja_env.from_string(value)
  File "/home/guilherme/airflow/venv/lib/python3.9/site-packages/jinja2/environment.py", line 1092, in from_string
    return cls.from_code(self, self.compile(source), gs, None)
  File "/home/guilherme/airflow/venv/lib/python3.9/site-packages/jinja2/environment.py", line 757, in compile
    self.handle_exception(source=source_hint)
  File "/home/guilherme/airflow/venv/lib/python3.9/site-packages/jinja2/environment.py", line 925, in handle_exception
    raise rewrite_traceback_stack(source=source)
  File "<unknown>", line 1, in template
jinja2.exceptions.TemplateSyntaxError: unexpected end of template, expected ','.
[2023-08-15 20:04:36,140] {taskinstance.py:1395} INFO - Marking task as FAILED. dag_id=dados_climaticos, task_id=cria_pasta, execution_date=20230522T000000, start_date=20230815T200435, end_date=20230815T200436
[2023-08-15 20:04:36,165] {standard_task_runner.py:92} ERROR - Failed to execute job 62 for task cria_pasta (unexpected end of template, expected ','.; 45192)
[2023-08-15 20:04:36,171] {local_task_job.py:156} INFO - Task exited with return code 1
[2023-08-15 20:04:36,210] {local_task_job.py:273} INFO - 0 downstream tasks scheduled from follow-on schedule check
[2023-08-15 20:11:16,754] {taskinstance.py:1159} INFO - Dependencies all met for <TaskInstance: dados_climaticos.cria_pasta scheduled__2023-05-22T00:00:00+00:00 [queued]>
[2023-08-15 20:11:16,760] {taskinstance.py:1159} INFO - Dependencies all met for <TaskInstance: dados_climaticos.cria_pasta scheduled__2023-05-22T00:00:00+00:00 [queued]>
[2023-08-15 20:11:16,760] {taskinstance.py:1356} INFO - 
--------------------------------------------------------------------------------
[2023-08-15 20:11:16,760] {taskinstance.py:1357} INFO - Starting attempt 1 of 1
[2023-08-15 20:11:16,760] {taskinstance.py:1358} INFO - 
--------------------------------------------------------------------------------
[2023-08-15 20:11:16,787] {taskinstance.py:1377} INFO - Executing <Task(BashOperator): cria_pasta> on 2023-05-22 00:00:00+00:00
[2023-08-15 20:11:16,791] {standard_task_runner.py:52} INFO - Started process 47880 to run task
[2023-08-15 20:11:16,800] {standard_task_runner.py:79} INFO - Running: ['airflow', 'tasks', 'run', 'dados_climaticos', 'cria_pasta', 'scheduled__2023-05-22T00:00:00+00:00', '--job-id', '120', '--raw', '--subdir', 'DAGS_FOLDER/dados_climatics.py', '--cfg-path', '/tmp/tmp7jjvgf2k', '--error-file', '/tmp/tmpmn8fvnch']
[2023-08-15 20:11:16,801] {standard_task_runner.py:80} INFO - Job 120: Subtask cria_pasta
[2023-08-15 20:11:16,855] {task_command.py:370} INFO - Running <TaskInstance: dados_climaticos.cria_pasta scheduled__2023-05-22T00:00:00+00:00 [running]> on host ubuntu.internal.cloudapp.net
[2023-08-15 20:11:16,928] {taskinstance.py:1569} INFO - Exporting the following env vars:
AIRFLOW_CTX_DAG_OWNER=airflow
AIRFLOW_CTX_DAG_ID=dados_climaticos
AIRFLOW_CTX_TASK_ID=cria_pasta
AIRFLOW_CTX_EXECUTION_DATE=2023-05-22T00:00:00+00:00
AIRFLOW_CTX_TRY_NUMBER=1
AIRFLOW_CTX_DAG_RUN_ID=scheduled__2023-05-22T00:00:00+00:00
[2023-08-15 20:11:16,929] {subprocess.py:62} INFO - Tmp dir root location: 
 /tmp
[2023-08-15 20:11:16,930] {subprocess.py:74} INFO - Running command: ['bash', '-c', 'mkdir -p "/home/guilherme/airflow/semana=2023-05-29"']
[2023-08-15 20:11:16,936] {subprocess.py:85} INFO - Output:
[2023-08-15 20:11:16,939] {subprocess.py:96} INFO - Command exited with return code 0
[2023-08-15 20:11:16,977] {taskinstance.py:1395} INFO - Marking task as SUCCESS. dag_id=dados_climaticos, task_id=cria_pasta, execution_date=20230522T000000, start_date=20230815T201116, end_date=20230815T201116
[2023-08-15 20:11:17,009] {local_task_job.py:156} INFO - Task exited with return code 0
[2023-08-15 20:11:17,045] {local_task_job.py:273} INFO - 1 downstream tasks scheduled from follow-on schedule check
