[2023-08-15 20:09:33,130] {taskinstance.py:1159} INFO - Dependencies all met for <TaskInstance: dados_climaticos.cria_pasta_mes_ano scheduled__2023-03-06T00:00:00+00:00 [queued]>
[2023-08-15 20:09:33,135] {taskinstance.py:1159} INFO - Dependencies all met for <TaskInstance: dados_climaticos.cria_pasta_mes_ano scheduled__2023-03-06T00:00:00+00:00 [queued]>
[2023-08-15 20:09:33,135] {taskinstance.py:1356} INFO - 
--------------------------------------------------------------------------------
[2023-08-15 20:09:33,135] {taskinstance.py:1357} INFO - Starting attempt 1 of 1
[2023-08-15 20:09:33,135] {taskinstance.py:1358} INFO - 
--------------------------------------------------------------------------------
[2023-08-15 20:09:33,163] {taskinstance.py:1377} INFO - Executing <Task(BashOperator): cria_pasta_mes_ano> on 2023-03-06 00:00:00+00:00
[2023-08-15 20:09:33,167] {standard_task_runner.py:52} INFO - Started process 47324 to run task
[2023-08-15 20:09:33,173] {standard_task_runner.py:79} INFO - Running: ['airflow', 'tasks', 'run', 'dados_climaticos', 'cria_pasta_mes_ano', 'scheduled__2023-03-06T00:00:00+00:00', '--job-id', '106', '--raw', '--subdir', 'DAGS_FOLDER/dados_climatics.py', '--cfg-path', '/tmp/tmpxx5cya2s', '--error-file', '/tmp/tmpzrv3hxoe']
[2023-08-15 20:09:33,174] {standard_task_runner.py:80} INFO - Job 106: Subtask cria_pasta_mes_ano
[2023-08-15 20:09:33,231] {task_command.py:370} INFO - Running <TaskInstance: dados_climaticos.cria_pasta_mes_ano scheduled__2023-03-06T00:00:00+00:00 [running]> on host ubuntu.internal.cloudapp.net
[2023-08-15 20:09:33,269] {taskinstance.py:1889} ERROR - Task failed with exception
Traceback (most recent call last):
  File "/home/guilherme/airflow/venv/lib/python3.9/site-packages/airflow/models/taskinstance.py", line 1451, in _run_raw_task
    self._execute_task_with_callbacks(context, test_mode)
  File "/home/guilherme/airflow/venv/lib/python3.9/site-packages/airflow/models/taskinstance.py", line 1555, in _execute_task_with_callbacks
    task_orig = self.render_templates(context=context)
  File "/home/guilherme/airflow/venv/lib/python3.9/site-packages/airflow/models/taskinstance.py", line 2212, in render_templates
    rendered_task = self.task.render_template_fields(context)
  File "/home/guilherme/airflow/venv/lib/python3.9/site-packages/airflow/models/baseoperator.py", line 1185, in render_template_fields
    self._do_render_template_fields(self, self.template_fields, context, jinja_env, set())
  File "/home/guilherme/airflow/venv/lib/python3.9/site-packages/airflow/utils/session.py", line 71, in wrapper
    return func(*args, session=session, **kwargs)
  File "/home/guilherme/airflow/venv/lib/python3.9/site-packages/airflow/models/abstractoperator.py", line 344, in _do_render_template_fields
    rendered_content = self.render_template(
  File "/home/guilherme/airflow/venv/lib/python3.9/site-packages/airflow/models/abstractoperator.py", line 387, in render_template
    template = jinja_env.from_string(value)
  File "/home/guilherme/airflow/venv/lib/python3.9/site-packages/jinja2/environment.py", line 1092, in from_string
    return cls.from_code(self, self.compile(source), gs, None)
  File "/home/guilherme/airflow/venv/lib/python3.9/site-packages/jinja2/environment.py", line 757, in compile
    self.handle_exception(source=source_hint)
  File "/home/guilherme/airflow/venv/lib/python3.9/site-packages/jinja2/environment.py", line 925, in handle_exception
    raise rewrite_traceback_stack(source=source)
  File "<unknown>", line 1, in template
jinja2.exceptions.TemplateSyntaxError: unexpected end of template, expected ','.
[2023-08-15 20:09:33,273] {taskinstance.py:1395} INFO - Marking task as FAILED. dag_id=dados_climaticos, task_id=cria_pasta_mes_ano, execution_date=20230306T000000, start_date=20230815T200933, end_date=20230815T200933
[2023-08-15 20:09:33,302] {standard_task_runner.py:92} ERROR - Failed to execute job 106 for task cria_pasta_mes_ano (unexpected end of template, expected ','.; 47324)
[2023-08-15 20:09:33,345] {local_task_job.py:156} INFO - Task exited with return code 1
[2023-08-15 20:09:33,385] {local_task_job.py:273} INFO - 0 downstream tasks scheduled from follow-on schedule check
[2023-08-15 20:28:18,576] {taskinstance.py:1159} INFO - Dependencies all met for <TaskInstance: dados_climaticos.cria_pasta_mes_ano scheduled__2023-03-06T00:00:00+00:00 [queued]>
[2023-08-15 20:28:18,583] {taskinstance.py:1159} INFO - Dependencies all met for <TaskInstance: dados_climaticos.cria_pasta_mes_ano scheduled__2023-03-06T00:00:00+00:00 [queued]>
[2023-08-15 20:28:18,583] {taskinstance.py:1356} INFO - 
--------------------------------------------------------------------------------
[2023-08-15 20:28:18,583] {taskinstance.py:1357} INFO - Starting attempt 1 of 1
[2023-08-15 20:28:18,583] {taskinstance.py:1358} INFO - 
--------------------------------------------------------------------------------
[2023-08-15 20:28:18,610] {taskinstance.py:1377} INFO - Executing <Task(BashOperator): cria_pasta_mes_ano> on 2023-03-06 00:00:00+00:00
[2023-08-15 20:28:18,614] {standard_task_runner.py:52} INFO - Started process 51289 to run task
[2023-08-15 20:28:18,620] {standard_task_runner.py:79} INFO - Running: ['airflow', 'tasks', 'run', 'dados_climaticos', 'cria_pasta_mes_ano', 'scheduled__2023-03-06T00:00:00+00:00', '--job-id', '158', '--raw', '--subdir', 'DAGS_FOLDER/dados_climatics.py', '--cfg-path', '/tmp/tmpmfvqzf_e', '--error-file', '/tmp/tmpjs_t4_1p']
[2023-08-15 20:28:18,621] {standard_task_runner.py:80} INFO - Job 158: Subtask cria_pasta_mes_ano
[2023-08-15 20:28:18,696] {task_command.py:370} INFO - Running <TaskInstance: dados_climaticos.cria_pasta_mes_ano scheduled__2023-03-06T00:00:00+00:00 [running]> on host ubuntu.internal.cloudapp.net
[2023-08-15 20:28:18,765] {taskinstance.py:1569} INFO - Exporting the following env vars:
AIRFLOW_CTX_DAG_OWNER=airflow
AIRFLOW_CTX_DAG_ID=dados_climaticos
AIRFLOW_CTX_TASK_ID=cria_pasta_mes_ano
AIRFLOW_CTX_EXECUTION_DATE=2023-03-06T00:00:00+00:00
AIRFLOW_CTX_TRY_NUMBER=1
AIRFLOW_CTX_DAG_RUN_ID=scheduled__2023-03-06T00:00:00+00:00
[2023-08-15 20:28:18,766] {subprocess.py:62} INFO - Tmp dir root location: 
 /tmp
[2023-08-15 20:28:18,766] {subprocess.py:74} INFO - Running command: ['bash', '-c', 'mkdir -p "/home/guilherme/airflow/semana=2023-03"']
[2023-08-15 20:28:18,773] {subprocess.py:85} INFO - Output:
[2023-08-15 20:28:18,775] {subprocess.py:96} INFO - Command exited with return code 0
[2023-08-15 20:28:18,808] {taskinstance.py:1395} INFO - Marking task as SUCCESS. dag_id=dados_climaticos, task_id=cria_pasta_mes_ano, execution_date=20230306T000000, start_date=20230815T202818, end_date=20230815T202818
[2023-08-15 20:28:18,836] {local_task_job.py:156} INFO - Task exited with return code 0
[2023-08-15 20:28:18,869] {local_task_job.py:273} INFO - 1 downstream tasks scheduled from follow-on schedule check
[2023-08-15 20:43:26,264] {taskinstance.py:1159} INFO - Dependencies all met for <TaskInstance: dados_climaticos.cria_pasta_mes_ano scheduled__2023-03-06T00:00:00+00:00 [queued]>
[2023-08-15 20:43:26,284] {taskinstance.py:1159} INFO - Dependencies all met for <TaskInstance: dados_climaticos.cria_pasta_mes_ano scheduled__2023-03-06T00:00:00+00:00 [queued]>
[2023-08-15 20:43:26,285] {taskinstance.py:1356} INFO - 
--------------------------------------------------------------------------------
[2023-08-15 20:43:26,285] {taskinstance.py:1357} INFO - Starting attempt 1 of 1
[2023-08-15 20:43:26,285] {taskinstance.py:1358} INFO - 
--------------------------------------------------------------------------------
[2023-08-15 20:43:26,337] {taskinstance.py:1377} INFO - Executing <Task(BashOperator): cria_pasta_mes_ano> on 2023-03-06 00:00:00+00:00
[2023-08-15 20:43:26,349] {standard_task_runner.py:52} INFO - Started process 56607 to run task
[2023-08-15 20:43:26,366] {standard_task_runner.py:79} INFO - Running: ['airflow', 'tasks', 'run', 'dados_climaticos', 'cria_pasta_mes_ano', 'scheduled__2023-03-06T00:00:00+00:00', '--job-id', '262', '--raw', '--subdir', 'DAGS_FOLDER/dados_climatics.py', '--cfg-path', '/tmp/tmp7sa27uxc', '--error-file', '/tmp/tmp8xw_ql8j']
[2023-08-15 20:43:26,370] {standard_task_runner.py:80} INFO - Job 262: Subtask cria_pasta_mes_ano
[2023-08-15 20:43:26,561] {task_command.py:370} INFO - Running <TaskInstance: dados_climaticos.cria_pasta_mes_ano scheduled__2023-03-06T00:00:00+00:00 [running]> on host ubuntu.internal.cloudapp.net
[2023-08-15 20:43:26,725] {taskinstance.py:1569} INFO - Exporting the following env vars:
AIRFLOW_CTX_DAG_OWNER=airflow
AIRFLOW_CTX_DAG_ID=dados_climaticos
AIRFLOW_CTX_TASK_ID=cria_pasta_mes_ano
AIRFLOW_CTX_EXECUTION_DATE=2023-03-06T00:00:00+00:00
AIRFLOW_CTX_TRY_NUMBER=1
AIRFLOW_CTX_DAG_RUN_ID=scheduled__2023-03-06T00:00:00+00:00
[2023-08-15 20:43:26,726] {subprocess.py:62} INFO - Tmp dir root location: 
 /tmp
[2023-08-15 20:43:26,726] {subprocess.py:74} INFO - Running command: ['bash', '-c', 'mkdir -p "/home/guilherme/airflow/dados/semana=2023-03"']
[2023-08-15 20:43:26,767] {subprocess.py:85} INFO - Output:
[2023-08-15 20:43:26,776] {subprocess.py:96} INFO - Command exited with return code 0
[2023-08-15 20:43:26,842] {taskinstance.py:1395} INFO - Marking task as SUCCESS. dag_id=dados_climaticos, task_id=cria_pasta_mes_ano, execution_date=20230306T000000, start_date=20230815T204326, end_date=20230815T204326
[2023-08-15 20:43:26,896] {local_task_job.py:156} INFO - Task exited with return code 0
[2023-08-15 20:43:26,994] {local_task_job.py:273} INFO - 1 downstream tasks scheduled from follow-on schedule check
